Workbook

Sheet Visão Geral
B1: Semear · Visão Geral do Cronograma
B2: Dados do CSV do cronograma. Altere o Status na aba Cronograma e tudo se atualiza.
B4: Itens no cronograma | E4: % concluído (esforço) | H4: Concluído / planejado (dias) | K4: Itens bloqueados
B5: =COUNTA('cronograma-csv'!$A$2:$A$40) -> 39 | E5: =Scrum!K12 -> 0.84920635 | H5: =TEXT(Scrum!I12,"0.0")&" / "&TEXT(Scrum!H12,"0.0") -> 53.5 / 63.0 | K5: =COUNTIFS(Cronograma!$C$7:$C$45,"<>Epic",Cronograma!$O$7:$O$45,"Bloqueado") -> 2
B8: Sprints | E8: Período planejado | H8: Velocidade média (dias/sprint) | K8: Data de referência
B9: =COUNTA(Scrum!$B$6:$B$11) -> 6 | E9: =TEXT(Scrum!D12,"dd/mm")&" – "&TEXT(Scrum!E12,"dd/mm") -> 01/10 – 28/10 | H9: =IFERROR(AVERAGEIF(Scrum!$I$6:$I$11,">0"),0) -> 8.9166667 | K9: =DATA_REF -> 46321
B12: ="⚠ Módulo N8N com problemas em produção · entrega em aberto. Itens bloqueados: "&COUNTIFS(Cronograma!$C$7:$C$45,"<>Epic",Cronograma!$O$7:$O$45,"Bloqueado")&" · esforço em aberto: "&TEXT(SUMIFS(Cronograma!$P$7:$P$45,Cronograma!$O$7:$O$45,"Bloqueado"),"0.0")&" dias (sprint de suprimentos e segurança). Investigação registrada na aba Pesquisas." -> ⚠ Módulo N8N com problemas em produção · entrega em aberto. Itens bloqueados: 2 · esforço em aberto: 3.5 dias (sprint de suprimentos e segurança). Investigação registrada na aba Pesquisas.
B34: Mais gráficos (burnup, velocidade, componentes) na aba Scrum.

Sheet Cronograma
B1: Cronograma do Projeto
B2: Itens do CSV com datas, prazos e status. Edite só as células amarelas da coluna Status; o Gantt, o Scrum e a Visão Geral acompanham.
B4: Legenda: | D4: Concluído | F4: Em andamento | G4: Bloqueado | H4: A fazer | I4: Amarelo = entrada | Q4: =TEXT(Q6,"mm/yyyy") -> 10/2026
Q5: =CHOOSE(WEEKDAY(Q6),"D","S","T","Q","Q","S","S") -> Q | R5: =CHOOSE(WEEKDAY(R6),"D","S","T","Q","Q","S","S") -> S | S5: =CHOOSE(WEEKDAY(S6),"D","S","T","Q","Q","S","S") -> S | T5: =CHOOSE(WEEKDAY(T6),"D","S","T","Q","Q","S","S") -> D | U5: =CHOOSE(WEEKDAY(U6),"D","S","T","Q","Q","S","S") -> S | V5: =CHOOSE(WEEKDAY(V6),"D","S","T","Q","Q","S","S") -> T | W5: =CHOOSE(WEEKDAY(W6),"D","S","T","Q","Q","S","S") -> Q | X5: =CHOOSE(WEEKDAY(X6),"D","S","T","Q","Q","S","S") -> Q | ... AU5: =CHOOSE(WEEKDAY(AU6),"D","S","T","Q","Q","S","S") -> S
B6: ID | C6: Tipo | D6: Resumo | E6: Épico ID | F6: Épico | G6: Sprint | H6: Componente | I6: Prazo médio (texto) | J6: Mín (dias) | K6: Máx (dias) | L6: Média (dias) | M6: Início | N6: Fim | O6: Status | P6: Esforço (dias) | Q6: =MIN($M$7:$M$45) -> 46296 | R6: =Q6+1 -> 46297 | S6: =R6+1 -> 46298 | T6: =S6+1 -> 46299 | U6: =T6+1 -> 46300 | V6: =U6+1 -> 46301 | W6: =V6+1 -> 46302 | X6: =W6+1 -> 46303 | Y6: =X6+1 -> 46304 | ... AU6: =AT6+1 -> 46326
B7: ='cronograma-csv'!A2 -> 1000 | C7: ='cronograma-csv'!B2 -> Epic | D7: ='cronograma-csv'!C2 -> Produto e arquitetura | E7: =IF(C7="Epic",B7,IF(C7="Story",'cronograma-csv'!E2,INDEX('cronograma-csv'!$E$2:$E$40,MATCH('cronograma-csv'!F2,'cronograma-csv'!$A$2:$A$40,0)))) -> 1000 | F7: =INDEX($D$7:$D$45,MATCH(E7,$B$7:$B$45,0)) -> Produto e arquitetura | G7: =IF('cronograma-csv'!G2<>"",'cronograma-csv'!G2,IFERROR(INDEX('cronograma-csv'!$G$2:$G$40,MATCH(B7,'cronograma-csv'!$E$2:$E$40,0)),"—")) -> S01 - Descoberta e fundação | H7: ='cronograma-csv'!H2 -> Produto | I7: ='cronograma-csv'!I2 -> 2 a 3 semanas | J7: =VALUE(LEFT(I7,FIND(" ",I7)-1))*IF(ISNUMBER(SEARCH("semana",I7)),DIAS_SEMANA,1) -> 14 | K7: =IF(ISNUMBER(SEARCH(" a ",I7)),VALUE(MID(I7,FIND(" a ",I7)+3,FIND(" ",I7,FIND(" a ",I7)+3)-FIND(" a ",I7)-3)),VALUE(LEFT(I7,FIND(" ",I7)-1)))*IF(ISNUMBER(SEARCH("semana",I7)),DIAS_SEMANA,1) -> 21 | L7: =(J7+K7)/2 -> 17.5 | M7: =_xlfn.MINIFS(M8:M$45,E8:E$45,B7) -> 46296 | N7: =_xlfn.MAXIFS(N8:N$45,E8:E$45,B7) -> 46299 | O7: =IF(COUNTIFS(E8:E$45,B7,O8:O$45,"Bloqueado")>0,"Bloqueado",IF(COUNTIFS(E8:E$45,B7,O8:O$45,"Concluído")=COUNTIF(E8:E$45,B7),"Concluído",IF(COUNTIFS(E8:E$45,B7,O8:O$45,"A fazer")=COUNTIF(E8:E$45,B7),"A fazer","Em andamento"))) -> Concluído | P7: =IF(C7="Story",L7,0) -> 0
B8: ='cronograma-csv'!A3 -> 1001 | C8: ='cronograma-csv'!B3 -> Story | D8: ='cronograma-csv'!C3 -> Levantar requisitos e público-alvo | E8: =IF(C8="Epic",B8,IF(C8="Story",'cronograma-csv'!E3,INDEX('cronograma-csv'!$E$2:$E$40,MATCH('cronograma-csv'!F3,'cronograma-csv'!$A$2:$A$40,0)))) -> 1000 | F8: =INDEX($D$7:$D$45,MATCH(E8,$B$7:$B$45,0)) -> Produto e arquitetura | G8: =IF('cronograma-csv'!G3<>"",'cronograma-csv'!G3,IFERROR(INDEX('cronograma-csv'!$G$2:$G$40,MATCH(B8,'cronograma-csv'!$E$2:$E$40,0)),"—")) -> S01 - Descoberta e fundação | H8: ='cronograma-csv'!H3 -> Produto | I8: ='cronograma-csv'!I3 -> 3 a 5 dias | J8: =VALUE(LEFT(I8,FIND(" ",I8)-1))*IF(ISNUMBER(SEARCH("semana",I8)),DIAS_SEMANA,1) -> 3 | K8: =IF(ISNUMBER(SEARCH(" a ",I8)),VALUE(MID(I8,FIND(" a ",I8)+3,FIND(" ",I8,FIND(" a ",I8)+3)-FIND(" a ",I8)-3)),VALUE(LEFT(I8,FIND(" ",I8)-1)))*IF(ISNUMBER(SEARCH("semana",I8)),DIAS_SEMANA,1) -> 5 | L8: =(J8+K8)/2 -> 4 | M8: ='cronograma-csv'!J3 -> 46296 | N8: =M8+MAX(1,ROUNDUP(L8,0))-1 -> 46299 | O8: Concluído | P8: =IF(C8="Story",L8,0) -> 4
B9: ='cronograma-csv'!A4 -> 1002 | C9: ='cronograma-csv'!B4 -> Sub-task | D9: ='cronograma-csv'!C4 -> Mapear functionalities e fluxos | E9: =IF(C9="Epic",B9,IF(C9="Story",'cronograma-csv'!E4,INDEX('cronograma-csv'!$E$2:$E$40,MATCH('cronograma-csv'!F4,'cronograma-csv'!$A$2:$A$40,0)))) -> 1000 | F9: =INDEX($D$7:$D$45,MATCH(E9,$B$7:$B$45,0)) -> Produto e arquitetura | G9: =IF('cronograma-csv'!G4<>"",'cronograma-csv'!G4,IFERROR(INDEX('cronograma-csv'!$G$2:$G$40,MATCH(B9,'cronograma-csv'!$E$2:$E$40,0)),"—")) -> S01 - Descoberta e fundação | H9: ='cronograma-csv'!H4 -> Produto | I9: ='cronograma-csv'!I4 -> 1 a 2 dias | J9: =VALUE(LEFT(I9,FIND(" ",I9)-1))*IF(ISNUMBER(SEARCH("semana",I9)),DIAS_SEMANA,1) -> 1 | K9: =IF(ISNUMBER(SEARCH(" a ",I9)),VALUE(MID(I9,FIND(" a ",I9)+3,FIND(" ",I9,FIND(" a ",I9)+3)-FIND(" a ",I9)-3)),VALUE(LEFT(I9,FIND(" ",I9)-1)))*IF(ISNUMBER(SEARCH("semana",I9)),DIAS_SEMANA,1) -> 2 | L9: =(J9+K9)/2 -> 1.5 | M9: ='cronograma-csv'!J4 -> 46297 | N9: =M9+MAX(1,ROUNDUP(L9,0))-1 -> 46298 | O9: Concluído | P9: =IF(C9="Story",L9,0) -> 0
B10: ='cronograma-csv'!A5 -> 1003 | C10: ='cronograma-csv'!B5 -> Story | D10: ='cronograma-csv'!C5 -> Definir arquitetura e modelo de dados | E10: =IF(C10="Epic",B10,IF(C10="Story",'cronograma-csv'!E5,INDEX('cronograma-csv'!$E$2:$E$40,MATCH('cronograma-csv'!F5,'cronograma-csv'!$A$2:$A$40,0)))) -> 1000 | F10: =INDEX($D$7:$D$45,MATCH(E10,$B$7:$B$45,0)) -> Produto e arquitetura | G10: =IF('cronograma-csv'!G5<>"",'cronograma-csv'!G5,IFERROR(INDEX('cronograma-csv'!$G$2:$G$40,MATCH(B10,'cronograma-csv'!$E$2:$E$40,0)),"—")) -> S01 - Descoberta e fundação | H10: ='cronograma-csv'!H5 -> Arquitetura | I10: ='cronograma-csv'!I5 -> 3 a 5 dias | J10: =VALUE(LEFT(I10,FIND(" ",I10)-1))*IF(ISNUMBER(SEARCH("semana",I10)),DIAS_SEMANA,1) -> 3 | K10: =IF(ISNUMBER(SEARCH(" a ",I10)),VALUE(MID(I10,FIND(" a ",I10)+3,FIND(" ",I10,FIND(" a ",I10)+3)-FIND(" a ",I10)-3)),VALUE(LEFT(I10,FIND(" ",I10)-1)))*IF(ISNUMBER(SEARCH("semana",I10)),DIAS_SEMANA,1) -> 5 | L10: =(J10+K10)/2 -> 4 | M10: ='cronograma-csv'!J5 -> 46296 | N10: =M10+MAX(1,ROUNDUP(L10,0))-1 -> 46299 | O10: Concluído | P10: =IF(C10="Story",L10,0) -> 4
B11: ='cronograma-csv'!A6 -> 1004 | C11: ='cronograma-csv'!B6 -> Sub-task | D11: ='cronograma-csv'!C6 -> Preparar ambiente e repositório | E11: =IF(C11="Epic",B11,IF(C11="Story",'cronograma-csv'!E6,INDEX('cronograma-csv'!$E$2:$E$40,MATCH('cronograma-csv'!F6,'cronograma-csv'!$A$2:$A$40,0)))) -> 1000 | F11: =INDEX($D$7:$D$45,MATCH(E11,$B$7:$B$45,0)) -> Produto e arquitetura | G11: =IF('cronograma-csv'!G6<>"",'cronograma-csv'!G6,IFERROR(INDEX('cronograma-csv'!$G$2:$G$40,MATCH(B11,'cronograma-csv'!$E$2:$E$40,0)),"—")) -> S01 - Descoberta e fundação | H11: ='cronograma-csv'!H6 -> DevOps | I11: ='cronograma-csv'!I6 -> 1 a 2 dias | J11: =VALUE(LEFT(I11,FIND(" ",I11)-1))*IF(ISNUMBER(SEARCH("semana",I11)),DIAS_SEMANA,1) -> 1 | K11: =IF(ISNUMBER(SEARCH(" a ",I11)),VALUE(MID(I11,FIND(" a ",I11)+3,FIND(" ",I11,FIND(" a ",I11)+3)-FIND(" a ",I11)-3)),VALUE(LEFT(I11,FIND(" ",I11)-1)))*IF(ISNUMBER(SEARCH("semana",I11)),DIAS_SEMANA,1) -> 2 | L11: =(J11+K11)/2 -> 1.5 | M11: ='cronograma-csv'!J6 -> 46297 | N11: =M11+MAX(1,ROUNDUP(L11,0))-1 -> 46298 | O11: Concluído | P11: =IF(C11="Story",L11,0) -> 0
B12: ='cronograma-csv'!A7 -> 1100 | C12: ='cronograma-csv'!B7 -> Epic | D12: ='cronograma-csv'!C7 -> API e persistência de dados | E12: =IF(C12="Epic",B12,IF(C12="Story",'cronograma-csv'!E7,INDEX('cronograma-csv'!$E$2:$E$40,MATCH('cronograma-csv'!F7,'cronograma-csv'!$A$2:$A$40,0)))) -> 1100 | F12: =INDEX($D$7:$D$45,MATCH(E12,$B$7:$B$45,0)) -> API e persistência de dados | G12: =IF('cronograma-csv'!G7<>"",'cronograma-csv'!G7,IFERROR(INDEX('cronograma-csv'!$G$2:$G$40,MATCH(B12,'cronograma-csv'!$E$2:$E$40,0)),"—")) -> S02 - API e dados | H12: ='cronograma-csv'!H7 -> Backend | I12: ='cronograma-csv'!I7 -> 3 a 4 semanas | J12: =VALUE(LEFT(I12,FIND(" ",I12)-1))*IF(ISNUMBER(SEARCH("semana",I12)),DIAS_SEMANA,1) -> 21 | K12: =IF(ISNUMBER(SEARCH(" a ",I12)),VALUE(MID(I12,FIND(" a ",I12)+3,FIND(" ",I12,FIND(" a ",I12)+3)-FIND(" a ",I12)-3)),VALUE(LEFT(I12,FIND(" ",I12)-1)))*IF(ISNUMBER(SEARCH("semana",I12)),DIAS_SEMANA,1) -> 28 | L12: =(J12+K12)/2 -> 24.5 | M12: =_xlfn.MINIFS(M13:M$45,E13:E$45,B12) -> 46301 | N12: =_xlfn.MAXIFS(N13:N$45,E13:E$45,B12) -> 46305 | O12: =IF(COUNTIFS(E13:E$45,B12,O13:O$45,"Bloqueado")>0,"Bloqueado",IF(COUNTIFS(E13:E$45,B12,O13:O$45,"Concluído")=COUNTIF(E13:E$45,B12),"Concluído",IF(COUNTIFS(E13:E$45,B12,O13:O$45,"A fazer")=COUNTIF(E13:E$45,B12),"A fazer","Em andamento"))) -> Concluído | P12: =IF(C12="Story",L12,0) -> 0
B13: ='cronograma-csv'!A8 -> 1101 | C13: ='cronograma-csv'!B8 -> Story | D13: ='cronograma-csv'!C8 -> Implementar esquema e persistência | E13: =IF(C13="Epic",B13,IF(C13="Story",'cronograma-csv'!E8,INDEX('cronograma-csv'!$E$2:$E$40,MATCH('cronograma-csv'!F8,'cronograma-csv'!$A$2:$A$40,0)))) -> 1100 | F13: =INDEX($D$7:$D$45,MATCH(E13,$B$7:$B$45,0)) -> API e persistência de dados | G13: =IF('cronograma-csv'!G8<>"",'cronograma-csv'!G8,IFERROR(INDEX('cronograma-csv'!$G$2:$G$40,MATCH(B13,'cronograma-csv'!$E$2:$E$40,0)),"—")) -> S02 - API e dados | H13: ='cronograma-csv'!H8 -> Backend | I13: ='cronograma-csv'!I8 -> 3 a 4 dias | J13: =VALUE(LEFT(I13,FIND(" ",I13)-1))*IF(ISNUMBER(SEARCH("semana",I13)),DIAS_SEMANA,1) -> 3 | K13: =IF(ISNUMBER(SEARCH(" a ",I13)),VALUE(MID(I13,FIND(" a ",I13)+3,FIND(" ",I13,FIND(" a ",I13)+3)-FIND(" a ",I13)-3)),VALUE(LEFT(I13,FIND(" ",I13)-1)))*IF(ISNUMBER(SEARCH("semana",I13)),DIAS_SEMANA,1) -> 4 | L13: =(J13+K13)/2 -> 3.5 | M13: ='cronograma-csv'!J8 -> 46301 | N13: =M13+MAX(1,ROUNDUP(L13,0))-1 -> 46304 | O13: Concluído | P13: =IF(C13="Story",L13,0) -> 3.5
B14: ='cronograma-csv'!A9 -> 1102 | C14: ='cronograma-csv'!B9 -> Sub-task | D14: ='cronograma-csv'!C9 -> Configurar PostgreSQL e scripts | E14: =IF(C14="Epic",B14,IF(C14="Story",'cronograma-csv'!E9,INDEX('cronograma-csv'!$E$2:$E$40,MATCH('cronograma-csv'!F9,'cronograma-csv'!$A$2:$A$40,0)))) -> 1100 | F14: =INDEX($D$7:$D$45,MATCH(E14,$B$7:$B$45,0)) -> API e persistência de dados | G14: =IF('cronograma-csv'!G9<>"",'cronograma-csv'!G9,IFERROR(INDEX('cronograma-csv'!$G$2:$G$40,MATCH(B14,'cronograma-csv'!$E$2:$E$40,0)),"—")) -> S02 - API e dados | H14: ='cronograma-csv'!H9 -> Dados | I14: ='cronograma-csv'!I9 -> 1 a 2 dias | J14: =VALUE(LEFT(I14,FIND(" ",I14)-1))*IF(ISNUMBER(SEARCH("semana",I14)),DIAS_SEMANA,1) -> 1 | K14: =IF(ISNUMBER(SEARCH(" a ",I14)),VALUE(MID(I14,FIND(" a ",I14)+3,FIND(" ",I14,FIND(" a ",I14)+3)-FIND(" a ",I14)-3)),VALUE(LEFT(I14,FIND(" ",I14)-1)))*IF(ISNUMBER(SEARCH("semana",I14)),DIAS_SEMANA,1) -> 2 | L14: =(J14+K14)/2 -> 1.5 | M14: ='cronograma-csv'!J9 -> 46302 | N14: =M14+MAX(1,ROUNDUP(L14,0))-1 -> 46303 | O14: Concluído | P14: =IF(C14="Story",L14,0) -> 0
B15: ='cronograma-csv'!A10 -> 1103 | C15: ='cronograma-csv'!B10 -> Story | D15: ='cronograma-csv'!C10 -> Disponibilizar endpoints de cadastros | E15: =IF(C15="Epic",B15,IF(C15="Story",'cronograma-csv'!E10,INDEX('cronograma-csv'!$E$2:$E$40,MATCH('cronograma-csv'!F10,'cronograma-csv'!$A$2:$A$40,0)))) -> 1100 | F15: =INDEX($D$7:$D$45,MATCH(E15,$B$7:$B$45,0)) -> API e persistência de dados | G15: =IF('cronograma-csv'!G10<>"",'cronograma-csv'!G10,IFERROR(INDEX('cronograma-csv'!$G$2:$G$40,MATCH(B15,'cronograma-csv'!$E$2:$E$40,0)),"—")) -> S02 - API e dados | H15: ='cronograma-csv'!H10 -> Backend | I15: ='cronograma-csv'!I10 -> 4 a 5 dias | J15: =VALUE(LEFT(I15,FIND(" ",I15)-1))*IF(ISNUMBER(SEARCH("semana",I15)),DIAS_SEMANA,1) -> 4 | K15: =IF(ISNUMBER(SEARCH(" a ",I15)),VALUE(MID(I15,FIND(" a ",I15)+3,FIND(" ",I15,FIND(" a ",I15)+3)-FIND(" a ",I15)-3)),VALUE(LEFT(I15,FIND(" ",I15)-1)))*IF(ISNUMBER(SEARCH("semana",I15)),DIAS_SEMANA,1) -> 5 | L15: =(J15+K15)/2 -> 4.5 | M15: ='cronograma-csv'!J10 -> 46301 | N15: =M15+MAX(1,ROUNDUP(L15,0))-1 -> 46305 | O15: Concluído | P15: =IF(C15="Story",L15,0) -> 4.5
B16: ='cronograma-csv'!A11 -> 1104 | C16: ='cronograma-csv'!B11 -> Sub-task | D16: ='cronograma-csv'!C11 -> Validar regras e relacionamentos | E16: =IF(C16="Epic",B16,IF(C16="Story",'cronograma-csv'!E11,INDEX('cronograma-csv'!$E$2:$E$40,MATCH('cronograma-csv'!F11,'cronograma-csv'!$A$2:$A$40,0)))) -> 1100 | F16: =INDEX($D$7:$D$45,MATCH(E16,$B$7:$B$45,0)) -> API e persistência de dados | G16: =IF('cronograma-csv'!G11<>"",'cronograma-csv'!G11,IFERROR(INDEX('cronograma-csv'!$G$2:$G$40,MATCH(B16,'cronograma-csv'!$E$2:$E$40,0)),"—")) -> S02 - API e dados | H16: ='cronograma-csv'!H11 -> Backend | I16: ='cronograma-csv'!I11 -> 1 a 2 dias | J16: =VALUE(LEFT(I16,FIND(" ",I16)-1))*IF(ISNUMBER(SEARCH("semana",I16)),DIAS_SEMANA,1) -> 1 | K16: =IF(ISNUMBER(SEARCH(" a ",I16)),VALUE(MID(I16,FIND(" a ",I16)+3,FIND(" ",I16,FIND(" a ",I16)+3)-FIND(" a ",I16)-3)),VALUE(LEFT(I16,FIND(" ",I16)-1)))*IF(ISNUMBER(SEARCH("semana",I16)),DIAS_SEMANA,1) -> 2 | L16: =(J16+K16)/2 -> 1.5 | M16: ='cronograma-csv'!J11 -> 46302 | N16: =M16+MAX(1,ROUNDUP(L16,0))-1 -> 46303 | O16: Concluído | P16: =IF(C16="Story",L16,0) -> 0
B17: ='cronograma-csv'!A12 -> 1105 | C17: ='cronograma-csv'!B12 -> Story | D17: ='cronograma-csv'!C12 -> Implementar avaliações e indicadores de escola | E17: =IF(C17="Epic",B17,IF(C17="Story",'cronograma-csv'!E12,INDEX('cronograma-csv'!$E$2:$E$40,MATCH('cronograma-csv'!F12,'cronograma-csv'!$A$2:$A$40,0)))) -> 1100 | F17: =INDEX($D$7:$D$45,MATCH(E17,$B$7:$B$45,0)) -> API e persistência de dados | G17: =IF('cronograma-csv'!G12<>"",'cronograma-csv'!G12,IFERROR(INDEX('cronograma-csv'!$G$2:$G$40,MATCH(B17,'cronograma-csv'!$E$2:$E$40,0)),"—")) -> S02 - API e dados | H17: ='cronograma-csv'!H12 -> Backend | I17: ='cronograma-csv'!I12 -> 3 a 5 dias | J17: =VALUE(LEFT(I17,FIND(" ",I17)-1))*IF(ISNUMBER(SEARCH("semana",I17)),DIAS_SEMANA,1) -> 3 | K17: =IF(ISNUMBER(SEARCH(" a ",I17)),VALUE(MID(I17,FIND(" a ",I17)+3,FIND(" ",I17,FIND(" a ",I17)+3)-FIND(" a ",I17)-3)),VALUE(LEFT(I17,FIND(" ",I17)-1)))*IF(ISNUMBER(SEARCH("semana",I17)),DIAS_SEMANA,1) -> 5 | L17: =(J17+K17)/2 -> 4 | M17: ='cronograma-csv'!J12 -> 46301 | N17: =M17+MAX(1,ROUNDUP(L17,0))-1 -> 46304 | O17: Concluído | P17: =IF(C17="Story",L17,0) -> 4
B18: ='cronograma-csv'!A13 -> 1200 | C18: ='cronograma-csv'!B13 -> Epic | D18: ='cronograma-csv'!C13 -> Interface e gestão educacional | E18: =IF(C18="Epic",B18,IF(C18="Story",'cronograma-csv'!E13,INDEX('cronograma-csv'!$E$2:$E$40,MATCH('cronograma-csv'!F13,'cronograma-csv'!$A$2:$A$40,0)))) -> 1200 | F18: =INDEX($D$7:$D$45,MATCH(E18,$B$7:$B$45,0)) -> Interface e gestão educacional | G18: =IF('cronograma-csv'!G13<>"",'cronograma-csv'!G13,IFERROR(INDEX('cronograma-csv'!$G$2:$G$40,MATCH(B18,'cronograma-csv'!$E$2:$E$40,0)),"—")) -> S03 - Interface e cadastros | H18: ='cronograma-csv'!H13 -> Frontend | I18: ='cronograma-csv'!I13 -> 3 a 4 semanas | J18: =VALUE(LEFT(I18,FIND(" ",I18)-1))*IF(ISNUMBER(SEARCH("semana",I18)),DIAS_SEMANA,1) -> 21 | K18: =IF(ISNUMBER(SEARCH(" a ",I18)),VALUE(MID(I18,FIND(" a ",I18)+3,FIND(" ",I18,FIND(" a ",I18)+3)-FIND(" a ",I18)-3)),VALUE(LEFT(I18,FIND(" ",I18)-1)))*IF(ISNUMBER(SEARCH("semana",I18)),DIAS_SEMANA,1) -> 28 | L18: =(J18+K18)/2 -> 24.5 | M18: =_xlfn.MINIFS(M19:M$45,E19:E$45,B18) -> 46307 | N18: =_xlfn.MAXIFS(N19:N$45,E19:E$45,B18) -> 46311 | O18: =IF(COUNTIFS(E19:E$45,B18,O19:O$45,"Bloqueado")>0,"Bloqueado",IF(COUNTIFS(E19:E$45,B18,O19:O$45,"Concluído")=COUNTIF(E19:E$45,B18),"Concluído",IF(COUNTIFS(E19:E$45,B18,O19:O$45,"A fazer")=COUNTIF(E19:E$45,B18),"A fazer","Em andamento"))) -> Concluído | P18: =IF(C18="Story",L18,0) -> 0
B19: ='cronograma-csv'!A14 -> 1201 | C19: ='cronograma-csv'!B14 -> Story | D19: ='cronograma-csv'!C14 -> Criar estrutura de navegação e identidade visual | E19: =IF(C19="Epic",B19,IF(C19="Story",'cronograma-csv'!E14,INDEX('cronograma-csv'!$E$2:$E$40,MATCH('cronograma-csv'!F14,'cronograma-csv'!$A$2:$A$40,0)))) -> 1200 | F19: =INDEX($D$7:$D$45,MATCH(E19,$B$7:$B$45,0)) -> Interface e gestão educacional | G19: =IF('cronograma-csv'!G14<>"",'cronograma-csv'!G14,IFERROR(INDEX('cronograma-csv'!$G$2:$G$40,MATCH(B19,'cronograma-csv'!$E$2:$E$40,0)),"—")) -> S03 - Interface e cadastros | H19: ='cronograma-csv'!H14 -> Frontend | I19: ='cronograma-csv'!I14 -> 3 a 4 dias | J19: =VALUE(LEFT(I19,FIND(" ",I19)-1))*IF(ISNUMBER(SEARCH("semana",I19)),DIAS_SEMANA,1) -> 3 | K19: =IF(ISNUMBER(SEARCH(" a ",I19)),VALUE(MID(I19,FIND(" a ",I19)+3,FIND(" ",I19,FIND(" a ",I19)+3)-FIND(" a ",I19)-3)),VALUE(LEFT(I19,FIND(" ",I19)-1)))*IF(ISNUMBER(SEARCH("semana",I19)),DIAS_SEMANA,1) -> 4 | L19: =(J19+K19)/2 -> 3.5 | M19: ='cronograma-csv'!J14 -> 46307 | N19: =M19+MAX(1,ROUNDUP(L19,0))-1 -> 46310 | O19: Concluído | P19: =IF(C19="Story",L19,0) -> 3.5
B20: ='cronograma-csv'!A15 -> 1202 | C20: ='cronograma-csv'!B15 -> Sub-task | D20: ='cronograma-csv'!C15 -> Implementar componentes reutilizáveis | E20: =IF(C20="Epic",B20,IF(C20="Story",'cronograma-csv'!E15,INDEX('cronograma-csv'!$E$2:$E$40,MATCH('cronograma-csv'!F15,'cronograma-csv'!$A$2:$A$40,0)))) -> 1200 | F20: =INDEX($D$7:$D$45,MATCH(E20,$B$7:$B$45,0)) -> Interface e gestão educacional | G20: =IF('cronograma-csv'!G15<>"",'cronograma-csv'!G15,IFERROR(INDEX('cronograma-csv'!$G$2:$G$40,MATCH(B20,'cronograma-csv'!$E$2:$E$40,0)),"—")) -> S03 - Interface e cadastros | H20: ='cronograma-csv'!H15 -> Frontend | I20: ='cronograma-csv'!I15 -> 2 a 3 dias | J20: =VALUE(LEFT(I20,FIND(" ",I20)-1))*IF(ISNUMBER(SEARCH("semana",I20)),DIAS_SEMANA,1) -> 2 | K20: =IF(ISNUMBER(SEARCH(" a ",I20)),VALUE(MID(I20,FIND(" a ",I20)+3,FIND(" ",I20,FIND(" a ",I20)+3)-FIND(" a ",I20)-3)),VALUE(LEFT(I20,FIND(" ",I20)-1)))*IF(ISNUMBER(SEARCH("semana",I20)),DIAS_SEMANA,1) -> 3 | L20: =(J20+K20)/2 -> 2.5 | M20: ='cronograma-csv'!J15 -> 46308 | N20: =M20+MAX(1,ROUNDUP(L20,0))-1 -> 46310 | O20: Concluído | P20: =IF(C20="Story",L20,0) -> 0
B21: ='cronograma-csv'!A16 -> 1203 | C21: ='cronograma-csv'!B16 -> Story | D21: ='cronograma-csv'!C16 -> Construir telas de cadastros educacionais | E21: =IF(C21="Epic",B21,IF(C21="Story",'cronograma-csv'!E16,INDEX('cronograma-csv'!$E$2:$E$40,MATCH('cronograma-csv'!F16,'cronograma-csv'!$A$2:$A$40,0)))) -> 1200 | F21: =INDEX($D$7:$D$45,MATCH(E21,$B$7:$B$45,0)) -> Interface e gestão educacional | G21: =IF('cronograma-csv'!G16<>"",'cronograma-csv'!G16,IFERROR(INDEX('cronograma-csv'!$G$2:$G$40,MATCH(B21,'cronograma-csv'!$E$2:$E$40,0)),"—")) -> S03 - Interface e cadastros | H21: ='cronograma-csv'!H16 -> Frontend | I21: ='cronograma-csv'!I16 -> 4 a 5 dias | J21: =VALUE(LEFT(I21,FIND(" ",I21)-1))*IF(ISNUMBER(SEARCH("semana",I21)),DIAS_SEMANA,1) -> 4 | K21: =IF(ISNUMBER(SEARCH(" a ",I21)),VALUE(MID(I21,FIND(" a ",I21)+3,FIND(" ",I21,FIND(" a ",I21)+3)-FIND(" a ",I21)-3)),VALUE(LEFT(I21,FIND(" ",I21)-1)))*IF(ISNUMBER(SEARCH("semana",I21)),DIAS_SEMANA,1) -> 5 | L21: =(J21+K21)/2 -> 4.5 | M21: ='cronograma-csv'!J16 -> 46307 | N21: =M21+MAX(1,ROUNDUP(L21,0))-1 -> 46311 | O21: Concluído | P21: =IF(C21="Story",L21,0) -> 4.5
B22: ='cronograma-csv'!A17 -> 1204 | C22: ='cronograma-csv'!B17 -> Sub-task | D22: ='cronograma-csv'!C17 -> Implementar consulta e manutenção de registros | E22: =IF(C22="Epic",B22,IF(C22="Story",'cronograma-csv'!E17,INDEX('cronograma-csv'!$E$2:$E$40,MATCH('cronograma-csv'!F17,'cronograma-csv'!$A$2:$A$40,0)))) -> 1200 | F22: =INDEX($D$7:$D$45,MATCH(E22,$B$7:$B$45,0)) -> Interface e gestão educacional | G22: =IF('cronograma-csv'!G17<>"",'cronograma-csv'!G17,IFERROR(INDEX('cronograma-csv'!$G$2:$G$40,MATCH(B22,'cronograma-csv'!$E$2:$E$40,0)),"—")) -> S03 - Interface e cadastros | H22: ='cronograma-csv'!H17 -> Frontend | I22: ='cronograma-csv'!I17 -> 2 a 3 dias | J22: =VALUE(LEFT(I22,FIND(" ",I22)-1))*IF(ISNUMBER(SEARCH("semana",I22)),DIAS_SEMANA,1) -> 2 | K22: =IF(ISNUMBER(SEARCH(" a ",I22)),VALUE(MID(I22,FIND(" a ",I22)+3,FIND(" ",I22,FIND(" a ",I22)+3)-FIND(" a ",I22)-3)),VALUE(LEFT(I22,FIND(" ",I22)-1)))*IF(ISNUMBER(SEARCH("semana",I22)),DIAS_SEMANA,1) -> 3 | L22: =(J22+K22)/2 -> 2.5 | M22: ='cronograma-csv'!J17 -> 46308 | N22: =M22+MAX(1,ROUNDUP(L22,0))-1 -> 46310 | O22: Concluído | P22: =IF(C22="Story",L22,0) -> 0
B23: ='cronograma-csv'!A18 -> 1205 | C23: ='cronograma-csv'!B18 -> Story | D23: ='cronograma-csv'!C18 -> Importar cadastros a partir de planilhas | E23: =IF(C23="Epic",B23,IF(C23="Story",'cronograma-csv'!E18,INDEX('cronograma-csv'!$E$2:$E$40,MATCH('cronograma-csv'!F18,'cronograma-csv'!$A$2:$A$40,0)))) -> 1200 | F23: =INDEX($D$7:$D$45,MATCH(E23,$B$7:$B$45,0)) -> Interface e gestão educacional | G23: =IF('cronograma-csv'!G18<>"",'cronograma-csv'!G18,IFERROR(INDEX('cronograma-csv'!$G$2:$G$40,MATCH(B23,'cronograma-csv'!$E$2:$E$40,0)),"—")) -> S03 - Interface e cadastros | H23: ='cronograma-csv'!H18 -> Integrações | I23: ='cronograma-csv'!I18 -> 4 a 5 dias | J23: =VALUE(LEFT(I23,FIND(" ",I23)-1))*IF(ISNUMBER(SEARCH("semana",I23)),DIAS_SEMANA,1) -> 4 | K23: =IF(ISNUMBER(SEARCH(" a ",I23)),VALUE(MID(I23,FIND(" a ",I23)+3,FIND(" ",I23,FIND(" a ",I23)+3)-FIND(" a ",I23)-3)),VALUE(LEFT(I23,FIND(" ",I23)-1)))*IF(ISNUMBER(SEARCH("semana",I23)),DIAS_SEMANA,1) -> 5 | L23: =(J23+K23)/2 -> 4.5 | M23: ='cronograma-csv'!J18 -> 46307 | N23: =M23+MAX(1,ROUNDUP(L23,0))-1 -> 46311 | O23: Concluído | P23: =IF(C23="Story",L23,0) -> 4.5
B24: ='cronograma-csv'!A19 -> 1206 | C24: ='cronograma-csv'!B19 -> Sub-task | D24: ='cronograma-csv'!C19 -> Validar colunas e dependências de importação | E24: =IF(C24="Epic",B24,IF(C24="Story",'cronograma-csv'!E19,INDEX('cronograma-csv'!$E$2:$E$40,MATCH('cronograma-csv'!F19,'cronograma-csv'!$A$2:$A$40,0)))) -> 1200 | F24: =INDEX($D$7:$D$45,MATCH(E24,$B$7:$B$45,0)) -> Interface e gestão educacional | G24: =IF('cronograma-csv'!G19<>"",'cronograma-csv'!G19,IFERROR(INDEX('cronograma-csv'!$G$2:$G$40,MATCH(B24,'cronograma-csv'!$E$2:$E$40,0)),"—")) -> S03 - Interface e cadastros | H24: ='cronograma-csv'!H19 -> Integrações | I24: ='cronograma-csv'!I19 -> 1 a 2 dias | J24: =VALUE(LEFT(I24,FIND(" ",I24)-1))*IF(ISNUMBER(SEARCH("semana",I24)),DIAS_SEMANA,1) -> 1 | K24: =IF(ISNUMBER(SEARCH(" a ",I24)),VALUE(MID(I24,FIND(" a ",I24)+3,FIND(" ",I24,FIND(" a ",I24)+3)-FIND(" a ",I24)-3)),VALUE(LEFT(I24,FIND(" ",I24)-1)))*IF(ISNUMBER(SEARCH("semana",I24)),DIAS_SEMANA,1) -> 2 | L24: =(J24+K24)/2 -> 1.5 | M24: ='cronograma-csv'!J19 -> 46308 | N24: =M24+MAX(1,ROUNDUP(L24,0))-1 -> 46309 | O24: Concluído | P24: =IF(C24="Story",L24,0) -> 0
B25: ='cronograma-csv'!A20 -> 1300 | C25: ='cronograma-csv'!B20 -> Epic | D25: ='cronograma-csv'!C20 -> Avaliações e acompanhamento do ODS 4 | E25: =IF(C25="Epic",B25,IF(C25="Story",'cronograma-csv'!E20,INDEX('cronograma-csv'!$E$2:$E$40,MATCH('cronograma-csv'!F20,'cronograma-csv'!$A$2:$A$40,0)))) -> 1300 | F25: =INDEX($D$7:$D$45,MATCH(E25,$B$7:$B$45,0)) -> Avaliações e acompanhamento do ODS 4 | G25: =IF('cronograma-csv'!G20<>"",'cronograma-csv'!G20,IFERROR(INDEX('cronograma-csv'!$G$2:$G$40,MATCH(B25,'cronograma-csv'!$E$2:$E$40,0)),"—")) -> S04 - Avaliações e indicadores | H25: ='cronograma-csv'!H20 -> Dados e Analytics | I25: ='cronograma-csv'!I20 -> 2 a 3 semanas | J25: =VALUE(LEFT(I25,FIND(" ",I25)-1))*IF(ISNUMBER(SEARCH("semana",I25)),DIAS_SEMANA,1) -> 14 | K25: =IF(ISNUMBER(SEARCH(" a ",I25)),VALUE(MID(I25,FIND(" a ",I25)+3,FIND(" ",I25,FIND(" a ",I25)+3)-FIND(" a ",I25)-3)),VALUE(LEFT(I25,FIND(" ",I25)-1)))*IF(ISNUMBER(SEARCH("semana",I25)),DIAS_SEMANA,1) -> 21 | L25: =(J25+K25)/2 -> 17.5 | M25: =_xlfn.MINIFS(M26:M$45,E26:E$45,B25) -> 46312 | N25: =_xlfn.MAXIFS(N26:N$45,E26:E$45,B25) -> 46316 | O25: =IF(COUNTIFS(E26:E$45,B25,O26:O$45,"Bloqueado")>0,"Bloqueado",IF(COUNTIFS(E26:E$45,B25,O26:O$45,"Concluído")=COUNTIF(E26:E$45,B25),"Concluído",IF(COUNTIFS(E26:E$45,B25,O26:O$45,"A fazer")=COUNTIF(E26:E$45,B25),"A fazer","Em andamento"))) -> Concluído | P25: =IF(C25="Story",L25,0) -> 0
B26: ='cronograma-csv'!A21 -> 1301 | C26: ='cronograma-csv'!B21 -> Story | D26: ='cronograma-csv'!C21 -> Criar telas de avaliação | E26: =IF(C26="Epic",B26,IF(C26="Story",'cronograma-csv'!E21,INDEX('cronograma-csv'!$E$2:$E$40,MATCH('cronograma-csv'!F21,'cronograma-csv'!$A$2:$A$40,0)))) -> 1300 | F26: =INDEX($D$7:$D$45,MATCH(E26,$B$7:$B$45,0)) -> Avaliações e acompanhamento do ODS 4 | G26: =IF('cronograma-csv'!G21<>"",'cronograma-csv'!G21,IFERROR(INDEX('cronograma-csv'!$G$2:$G$40,MATCH(B26,'cronograma-csv'!$E$2:$E$40,0)),"—")) -> S04 - Avaliações e indicadores | H26: ='cronograma-csv'!H21 -> Frontend | I26: ='cronograma-csv'!I21 -> 2 a 3 dias | J26: =VALUE(LEFT(I26,FIND(" ",I26)-1))*IF(ISNUMBER(SEARCH("semana",I26)),DIAS_SEMANA,1) -> 2 | K26: =IF(ISNUMBER(SEARCH(" a ",I26)),VALUE(MID(I26,FIND(" a ",I26)+3,FIND(" ",I26,FIND(" a ",I26)+3)-FIND(" a ",I26)-3)),VALUE(LEFT(I26,FIND(" ",I26)-1)))*IF(ISNUMBER(SEARCH("semana",I26)),DIAS_SEMANA,1) -> 3 | L26: =(J26+K26)/2 -> 2.5 | M26: ='cronograma-csv'!J21 -> 46312 | N26: =M26+MAX(1,ROUNDUP(L26,0))-1 -> 46314 | O26: Concluído | P26: =IF(C26="Story",L26,0) -> 2.5
B27: ='cronograma-csv'!A22 -> 1302 | C27: ='cronograma-csv'!B22 -> Sub-task | D27: ='cronograma-csv'!C22 -> Integrar avaliações à API | E27: =IF(C27="Epic",B27,IF(C27="Story",'cronograma-csv'!E22,INDEX('cronograma-csv'!$E$2:$E$40,MATCH('cronograma-csv'!F22,'cronograma-csv'!$A$2:$A$40,0)))) -> 1300 | F27: =INDEX($D$7:$D$45,MATCH(E27,$B$7:$B$45,0)) -> Avaliações e acompanhamento do ODS 4 | G27: =IF('cronograma-csv'!G22<>"",'cronograma-csv'!G22,IFERROR(INDEX('cronograma-csv'!$G$2:$G$40,MATCH(B27,'cronograma-csv'!$E$2:$E$40,0)),"—")) -> S04 - Avaliações e indicadores | H27: ='cronograma-csv'!H22 -> Backend | I27: ='cronograma-csv'!I22 -> 1 a 2 dias | J27: =VALUE(LEFT(I27,FIND(" ",I27)-1))*IF(ISNUMBER(SEARCH("semana",I27)),DIAS_SEMANA,1) -> 1 | K27: =IF(ISNUMBER(SEARCH(" a ",I27)),VALUE(MID(I27,FIND(" a ",I27)+3,FIND(" ",I27,FIND(" a ",I27)+3)-FIND(" a ",I27)-3)),VALUE(LEFT(I27,FIND(" ",I27)-1)))*IF(ISNUMBER(SEARCH("semana",I27)),DIAS_SEMANA,1) -> 2 | L27: =(J27+K27)/2 -> 1.5 | M27: ='cronograma-csv'!J22 -> 46313 | N27: =M27+MAX(1,ROUNDUP(L27,0))-1 -> 46314 | O27: Concluído | P27: =IF(C27="Story",L27,0) -> 0
B28: ='cronograma-csv'!A23 -> 1303 | C28: ='cronograma-csv'!B23 -> Story | D28: ='cronograma-csv'!C23 -> Construir dashboard e relatório gerencial | E28: =IF(C28="Epic",B28,IF(C28="Story",'cronograma-csv'!E23,INDEX('cronograma-csv'!$E$2:$E$40,MATCH('cronograma-csv'!F23,'cronograma-csv'!$A$2:$A$40,0)))) -> 1300 | F28: =INDEX($D$7:$D$45,MATCH(E28,$B$7:$B$45,0)) -> Avaliações e acompanhamento do ODS 4 | G28: =IF('cronograma-csv'!G23<>"",'cronograma-csv'!G23,IFERROR(INDEX('cronograma-csv'!$G$2:$G$40,MATCH(B28,'cronograma-csv'!$E$2:$E$40,0)),"—")) -> S04 - Avaliações e indicadores | H28: ='cronograma-csv'!H23 -> Dados e Analytics | I28: ='cronograma-csv'!I23 -> 4 a 5 dias | J28: =VALUE(LEFT(I28,FIND(" ",I28)-1))*IF(ISNUMBER(SEARCH("semana",I28)),DIAS_SEMANA,1) -> 4 | K28: =IF(ISNUMBER(SEARCH(" a ",I28)),VALUE(MID(I28,FIND(" a ",I28)+3,FIND(" ",I28,FIND(" a ",I28)+3)-FIND(" a ",I28)-3)),VALUE(LEFT(I28,FIND(" ",I28)-1)))*IF(ISNUMBER(SEARCH("semana",I28)),DIAS_SEMANA,1) -> 5 | L28: =(J28+K28)/2 -> 4.5 | M28: ='cronograma-csv'!J23 -> 46312 | N28: =M28+MAX(1,ROUNDUP(L28,0))-1 -> 46316 | O28: Concluído | P28: =IF(C28="Story",L28,0) -> 4.5
B29: ='cronograma-csv'!A24 -> 1304 | C29: ='cronograma-csv'!B24 -> Sub-task | D29: ='cronograma-csv'!C24 -> Implementar agregações e visualizações | E29: =IF(C29="Epic",B29,IF(C29="Story",'cronograma-csv'!E24,INDEX('cronograma-csv'!$E$2:$E$40,MATCH('cronograma-csv'!F24,'cronograma-csv'!$A$2:$A$40,0)))) -> 1300 | F29: =INDEX($D$7:$D$45,MATCH(E29,$B$7:$B$45,0)) -> Avaliações e acompanhamento do ODS 4 | G29: =IF('cronograma-csv'!G24<>"",'cronograma-csv'!G24,IFERROR(INDEX('cronograma-csv'!$G$2:$G$40,MATCH(B29,'cronograma-csv'!$E$2:$E$40,0)),"—")) -> S04 - Avaliações e indicadores | H29: ='cronograma-csv'!H24 -> Dados e Analytics | I29: ='cronograma-csv'!I24 -> 2 a 3 dias | J29: =VALUE(LEFT(I29,FIND(" ",I29)-1))*IF(ISNUMBER(SEARCH("semana",I29)),DIAS_SEMANA,1) -> 2 | K29: =IF(ISNUMBER(SEARCH(" a ",I29)),VALUE(MID(I29,FIND(" a ",I29)+3,FIND(" ",I29,FIND(" a ",I29)+3)-FIND(" a ",I29)-3)),VALUE(LEFT(I29,FIND(" ",I29)-1)))*IF(ISNUMBER(SEARCH("semana",I29)),DIAS_SEMANA,1) -> 3 | L29: =(J29+K29)/2 -> 2.5 | M29: ='cronograma-csv'!J24 -> 46313 | N29: =M29+MAX(1,ROUNDUP(L29,0))-1 -> 46315 | O29: Concluído | P29: =IF(C29="Story",L29,0) -> 0
B30: ='cronograma-csv'!A25 -> 1305 | C30: ='cronograma-csv'!B25 -> Story | D30: ='cronograma-csv'!C25 -> Apresentar contexto e mapa educacional | E30: =IF(C30="Epic",B30,IF(C30="Story",'cronograma-csv'!E25,INDEX('cronograma-csv'!$E$2:$E$40,MATCH('cronograma-csv'!F25,'cronograma-csv'!$A$2:$A$40,0)))) -> 1300 | F30: =INDEX($D$7:$D$45,MATCH(E30,$B$7:$B$45,0)) -> Avaliações e acompanhamento do ODS 4 | G30: =IF('cronograma-csv'!G25<>"",'cronograma-csv'!G25,IFERROR(INDEX('cronograma-csv'!$G$2:$G$40,MATCH(B30,'cronograma-csv'!$E$2:$E$40,0)),"—")) -> S04 - Avaliações e indicadores | H30: ='cronograma-csv'!H25 -> Frontend | I30: ='cronograma-csv'!I25 -> 3 a 4 dias | J30: =VALUE(LEFT(I30,FIND(" ",I30)-1))*IF(ISNUMBER(SEARCH("semana",I30)),DIAS_SEMANA,1) -> 3 | K30: =IF(ISNUMBER(SEARCH(" a ",I30)),VALUE(MID(I30,FIND(" a ",I30)+3,FIND(" ",I30,FIND(" a ",I30)+3)-FIND(" a ",I30)-3)),VALUE(LEFT(I30,FIND(" ",I30)-1)))*IF(ISNUMBER(SEARCH("semana",I30)),DIAS_SEMANA,1) -> 4 | L30: =(J30+K30)/2 -> 3.5 | M30: ='cronograma-csv'!J25 -> 46312 | N30: =M30+MAX(1,ROUNDUP(L30,0))-1 -> 46315 | O30: Concluído | P30: =IF(C30="Story",L30,0) -> 3.5
B31: ='cronograma-csv'!A26 -> 1306 | C31: ='cronograma-csv'!B26 -> Sub-task | D31: ='cronograma-csv'!C26 -> Integrar dados geográficos e fontes | E31: =IF(C31="Epic",B31,IF(C31="Story",'cronograma-csv'!E26,INDEX('cronograma-csv'!$E$2:$E$40,MATCH('cronograma-csv'!F26,'cronograma-csv'!$A$2:$A$40,0)))) -> 1300 | F31: =INDEX($D$7:$D$45,MATCH(E31,$B$7:$B$45,0)) -> Avaliações e acompanhamento do ODS 4 | G31: =IF('cronograma-csv'!G26<>"",'cronograma-csv'!G26,IFERROR(INDEX('cronograma-csv'!$G$2:$G$40,MATCH(B31,'cronograma-csv'!$E$2:$E$40,0)),"—")) -> S04 - Avaliações e indicadores | H31: ='cronograma-csv'!H26 -> Integrações | I31: ='cronograma-csv'!I26 -> 2 dias | J31: =VALUE(LEFT(I31,FIND(" ",I31)-1))*IF(ISNUMBER(SEARCH("semana",I31)),DIAS_SEMANA,1) -> 2 | K31: =IF(ISNUMBER(SEARCH(" a ",I31)),VALUE(MID(I31,FIND(" a ",I31)+3,FIND(" ",I31,FIND(" a ",I31)+3)-FIND(" a ",I31)-3)),VALUE(LEFT(I31,FIND(" ",I31)-1)))*IF(ISNUMBER(SEARCH("semana",I31)),DIAS_SEMANA,1) -> 2 | L31: =(J31+K31)/2 -> 2 | M31: ='cronograma-csv'!J26 -> 46313 | N31: =M31+MAX(1,ROUNDUP(L31,0))-1 -> 46314 | O31: Concluído | P31: =IF(C31="Story",L31,0) -> 0
B32: ='cronograma-csv'!A27 -> 1400 | C32: ='cronograma-csv'!B27 -> Epic | D32: ='cronograma-csv'!C27 -> Suprimentos e controle de acesso | E32: =IF(C32="Epic",B32,IF(C32="Story",'cronograma-csv'!E27,INDEX('cronograma-csv'!$E$2:$E$40,MATCH('cronograma-csv'!F27,'cronograma-csv'!$A$2:$A$40,0)))) -> 1400 | F32: =INDEX($D$7:$D$45,MATCH(E32,$B$7:$B$45,0)) -> Suprimentos e controle de acesso | G32: =IF('cronograma-csv'!G27<>"",'cronograma-csv'!G27,IFERROR(INDEX('cronograma-csv'!$G$2:$G$40,MATCH(B32,'cronograma-csv'!$E$2:$E$40,0)),"—")) -> S05 - Suprimentos e segurança | H32: ='cronograma-csv'!H27 -> Segurança | I32: ='cronograma-csv'!I27 -> 2 a 3 semanas | J32: =VALUE(LEFT(I32,FIND(" ",I32)-1))*IF(ISNUMBER(SEARCH("semana",I32)),DIAS_SEMANA,1) -> 14 | K32: =IF(ISNUMBER(SEARCH(" a ",I32)),VALUE(MID(I32,FIND(" a ",I32)+3,FIND(" ",I32,FIND(" a ",I32)+3)-FIND(" a ",I32)-3)),VALUE(LEFT(I32,FIND(" ",I32)-1)))*IF(ISNUMBER(SEARCH("semana",I32)),DIAS_SEMANA,1) -> 21 | L32: =(J32+K32)/2 -> 17.5 | M32: =_xlfn.MINIFS(M33:M$45,E33:E$45,B32) -> 46317 | N32: =_xlfn.MAXIFS(N33:N$45,E33:E$45,B32) -> 46320 | O32: =IF(COUNTIFS(E33:E$45,B32,O33:O$45,"Bloqueado")>0,"Bloqueado",IF(COUNTIFS(E33:E$45,B32,O33:O$45,"Concluído")=COUNTIF(E33:E$45,B32),"Concluído",IF(COUNTIFS(E33:E$45,B32,O33:O$45,"A fazer")=COUNTIF(E33:E$45,B32),"A fazer","Em andamento"))) -> Bloqueado | P32: =IF(C32="Story",L32,0) -> 0
B33: ='cronograma-csv'!A28 -> 1401 | C33: ='cronograma-csv'!B28 -> Story | D33: ='cronograma-csv'!C28 -> Gerenciar produtos e pedidos | E33: =IF(C33="Epic",B33,IF(C33="Story",'cronograma-csv'!E28,INDEX('cronograma-csv'!$E$2:$E$40,MATCH('cronograma-csv'!F28,'cronograma-csv'!$A$2:$A$40,0)))) -> 1400 | F33: =INDEX($D$7:$D$45,MATCH(E33,$B$7:$B$45,0)) -> Suprimentos e controle de acesso | G33: =IF('cronograma-csv'!G28<>"",'cronograma-csv'!G28,IFERROR(INDEX('cronograma-csv'!$G$2:$G$40,MATCH(B33,'cronograma-csv'!$E$2:$E$40,0)),"—")) -> S05 - Suprimentos e segurança | H33: ='cronograma-csv'!H28 -> Frontend | I33: ='cronograma-csv'!I28 -> 3 a 4 dias | J33: =VALUE(LEFT(I33,FIND(" ",I33)-1))*IF(ISNUMBER(SEARCH("semana",I33)),DIAS_SEMANA,1) -> 3 | K33: =IF(ISNUMBER(SEARCH(" a ",I33)),VALUE(MID(I33,FIND(" a ",I33)+3,FIND(" ",I33,FIND(" a ",I33)+3)-FIND(" a ",I33)-3)),VALUE(LEFT(I33,FIND(" ",I33)-1)))*IF(ISNUMBER(SEARCH("semana",I33)),DIAS_SEMANA,1) -> 4 | L33: =(J33+K33)/2 -> 3.5 | M33: ='cronograma-csv'!J28 -> 46317 | N33: =M33+MAX(1,ROUNDUP(L33,0))-1 -> 46320 | O33: Concluído | P33: =IF(C33="Story",L33,0) -> 3.5
B34: ='cronograma-csv'!A29 -> 1402 | C34: ='cronograma-csv'!B29 -> Sub-task | D34: ='cronograma-csv'!C29 -> Integrar fluxo de suprimentos à API | E34: =IF(C34="Epic",B34,IF(C34="Story",'cronograma-csv'!E29,INDEX('cronograma-csv'!$E$2:$E$40,MATCH('cronograma-csv'!F29,'cronograma-csv'!$A$2:$A$40,0)))) -> 1400 | F34: =INDEX($D$7:$D$45,MATCH(E34,$B$7:$B$45,0)) -> Suprimentos e controle de acesso | G34: =IF('cronograma-csv'!G29<>"",'cronograma-csv'!G29,IFERROR(INDEX('cronograma-csv'!$G$2:$G$40,MATCH(B34,'cronograma-csv'!$E$2:$E$40,0)),"—")) -> S05 - Suprimentos e segurança | H34: ='cronograma-csv'!H29 -> Backend | I34: ='cronograma-csv'!I29 -> 2 dias | J34: =VALUE(LEFT(I34,FIND(" ",I34)-1))*IF(ISNUMBER(SEARCH("semana",I34)),DIAS_SEMANA,1) -> 2 | K34: =IF(ISNUMBER(SEARCH(" a ",I34)),VALUE(MID(I34,FIND(" a ",I34)+3,FIND(" ",I34,FIND(" a ",I34)+3)-FIND(" a ",I34)-3)),VALUE(LEFT(I34,FIND(" ",I34)-1)))*IF(ISNUMBER(SEARCH("semana",I34)),DIAS_SEMANA,1) -> 2 | L34: =(J34+K34)/2 -> 2 | M34: ='cronograma-csv'!J29 -> 46318 | N34: =M34+MAX(1,ROUNDUP(L34,0))-1 -> 46319 | O34: Concluído | P34: =IF(C34="Story",L34,0) -> 0
B35: ='cronograma-csv'!A30 -> 1403 | C35: ='cronograma-csv'!B30 -> Story | D35: ='cronograma-csv'!C30 -> Proteger operações administrativas com autenticação | E35: =IF(C35="Epic",B35,IF(C35="Story",'cronograma-csv'!E30,INDEX('cronograma-csv'!$E$2:$E$40,MATCH('cronograma-csv'!F30,'cronograma-csv'!$A$2:$A$40,0)))) -> 1400 | F35: =INDEX($D$7:$D$45,MATCH(E35,$B$7:$B$45,0)) -> Suprimentos e controle de acesso | G35: =IF('cronograma-csv'!G30<>"",'cronograma-csv'!G30,IFERROR(INDEX('cronograma-csv'!$G$2:$G$40,MATCH(B35,'cronograma-csv'!$E$2:$E$40,0)),"—")) -> S05 - Suprimentos e segurança | H35: ='cronograma-csv'!H30 -> Segurança | I35: ='cronograma-csv'!I30 -> 3 a 5 dias | J35: =VALUE(LEFT(I35,FIND(" ",I35)-1))*IF(ISNUMBER(SEARCH("semana",I35)),DIAS_SEMANA,1) -> 3 | K35: =IF(ISNUMBER(SEARCH(" a ",I35)),VALUE(MID(I35,FIND(" a ",I35)+3,FIND(" ",I35,FIND(" a ",I35)+3)-FIND(" a ",I35)-3)),VALUE(LEFT(I35,FIND(" ",I35)-1)))*IF(ISNUMBER(SEARCH("semana",I35)),DIAS_SEMANA,1) -> 5 | L35: =(J35+K35)/2 -> 4 | M35: ='cronograma-csv'!J30 -> 46317 | N35: =M35+MAX(1,ROUNDUP(L35,0))-1 -> 46320 | O35: Concluído | P35: =IF(C35="Story",L35,0) -> 4
B36: ='cronograma-csv'!A31 -> 1404 | C36: ='cronograma-csv'!B31 -> Sub-task | D36: ='cronograma-csv'!C31 -> Aplicar autorização e controle de sessão | E36: =IF(C36="Epic",B36,IF(C36="Story",'cronograma-csv'!E31,INDEX('cronograma-csv'!$E$2:$E$40,MATCH('cronograma-csv'!F31,'cronograma-csv'!$A$2:$A$40,0)))) -> 1400 | F36: =INDEX($D$7:$D$45,MATCH(E36,$B$7:$B$45,0)) -> Suprimentos e controle de acesso | G36: =IF('cronograma-csv'!G31<>"",'cronograma-csv'!G31,IFERROR(INDEX('cronograma-csv'!$G$2:$G$40,MATCH(B36,'cronograma-csv'!$E$2:$E$40,0)),"—")) -> S05 - Suprimentos e segurança | H36: ='cronograma-csv'!H31 -> Segurança | I36: ='cronograma-csv'!I31 -> 2 dias | J36: =VALUE(LEFT(I36,FIND(" ",I36)-1))*IF(ISNUMBER(SEARCH("semana",I36)),DIAS_SEMANA,1) -> 2 | K36: =IF(ISNUMBER(SEARCH(" a ",I36)),VALUE(MID(I36,FIND(" a ",I36)+3,FIND(" ",I36,FIND(" a ",I36)+3)-FIND(" a ",I36)-3)),VALUE(LEFT(I36,FIND(" ",I36)-1)))*IF(ISNUMBER(SEARCH("semana",I36)),DIAS_SEMANA,1) -> 2 | L36: =(J36+K36)/2 -> 2 | M36: ='cronograma-csv'!J31 -> 46318 | N36: =M36+MAX(1,ROUNDUP(L36,0))-1 -> 46319 | O36: Concluído | P36: =IF(C36="Story",L36,0) -> 0
B37: ='cronograma-csv'!A32 -> 1405 | C37: ='cronograma-csv'!B32 -> Story | D37: ='cronograma-csv'!C32 -> Integrar automações e auditoria | E37: =IF(C37="Epic",B37,IF(C37="Story",'cronograma-csv'!E32,INDEX('cronograma-csv'!$E$2:$E$40,MATCH('cronograma-csv'!F32,'cronograma-csv'!$A$2:$A$40,0)))) -> 1400 | F37: =INDEX($D$7:$D$45,MATCH(E37,$B$7:$B$45,0)) -> Suprimentos e controle de acesso | G37: =IF('cronograma-csv'!G32<>"",'cronograma-csv'!G32,IFERROR(INDEX('cronograma-csv'!$G$2:$G$40,MATCH(B37,'cronograma-csv'!$E$2:$E$40,0)),"—")) -> S05 - Suprimentos e segurança | H37: ='cronograma-csv'!H32 -> Integrações | I37: ='cronograma-csv'!I32 -> 3 a 4 dias | J37: =VALUE(LEFT(I37,FIND(" ",I37)-1))*IF(ISNUMBER(SEARCH("semana",I37)),DIAS_SEMANA,1) -> 3 | K37: =IF(ISNUMBER(SEARCH(" a ",I37)),VALUE(MID(I37,FIND(" a ",I37)+3,FIND(" ",I37,FIND(" a ",I37)+3)-FIND(" a ",I37)-3)),VALUE(LEFT(I37,FIND(" ",I37)-1)))*IF(ISNUMBER(SEARCH("semana",I37)),DIAS_SEMANA,1) -> 4 | L37: =(J37+K37)/2 -> 3.5 | M37: ='cronograma-csv'!J32 -> 46317 | N37: =M37+MAX(1,ROUNDUP(L37,0))-1 -> 46320 | O37: Bloqueado | P37: =IF(C37="Story",L37,0) -> 3.5
B38: ='cronograma-csv'!A33 -> 1406 | C38: ='cronograma-csv'!B33 -> Sub-task | D38: ='cronograma-csv'!C33 -> Validar integração e registros de eventos | E38: =IF(C38="Epic",B38,IF(C38="Story",'cronograma-csv'!E33,INDEX('cronograma-csv'!$E$2:$E$40,MATCH('cronograma-csv'!F33,'cronograma-csv'!$A$2:$A$40,0)))) -> 1400 | F38: =INDEX($D$7:$D$45,MATCH(E38,$B$7:$B$45,0)) -> Suprimentos e controle de acesso | G38: =IF('cronograma-csv'!G33<>"",'cronograma-csv'!G33,IFERROR(INDEX('cronograma-csv'!$G$2:$G$40,MATCH(B38,'cronograma-csv'!$E$2:$E$40,0)),"—")) -> S05 - Suprimentos e segurança | H38: ='cronograma-csv'!H33 -> Qualidade | I38: ='cronograma-csv'!I33 -> 1 a 2 dias | J38: =VALUE(LEFT(I38,FIND(" ",I38)-1))*IF(ISNUMBER(SEARCH("semana",I38)),DIAS_SEMANA,1) -> 1 | K38: =IF(ISNUMBER(SEARCH(" a ",I38)),VALUE(MID(I38,FIND(" a ",I38)+3,FIND(" ",I38,FIND(" a ",I38)+3)-FIND(" a ",I38)-3)),VALUE(LEFT(I38,FIND(" ",I38)-1)))*IF(ISNUMBER(SEARCH("semana",I38)),DIAS_SEMANA,1) -> 2 | L38: =(J38+K38)/2 -> 1.5 | M38: ='cronograma-csv'!J33 -> 46318 | N38: =M38+MAX(1,ROUNDUP(L38,0))-1 -> 46319 | O38: Bloqueado | P38: =IF(C38="Story",L38,0) -> 0
B39: ='cronograma-csv'!A34 -> 1500 | C39: ='cronograma-csv'!B34 -> Epic | D39: ='cronograma-csv'!C34 -> Qualidade, publicação e documentação | E39: =IF(C39="Epic",B39,IF(C39="Story",'cronograma-csv'!E34,INDEX('cronograma-csv'!$E$2:$E$40,MATCH('cronograma-csv'!F34,'cronograma-csv'!$A$2:$A$40,0)))) -> 1500 | F39: =INDEX($D$7:$D$45,MATCH(E39,$B$7:$B$45,0)) -> Qualidade, publicação e documentação | G39: =IF('cronograma-csv'!G34<>"",'cronograma-csv'!G34,IFERROR(INDEX('cronograma-csv'!$G$2:$G$40,MATCH(B39,'cronograma-csv'!$E$2:$E$40,0)),"—")) -> S06 - Validação e entrega | H39: ='cronograma-csv'!H34 -> DevOps e Qualidade | I39: ='cronograma-csv'!I34 -> 2 semanas | J39: =VALUE(LEFT(I39,FIND(" ",I39)-1))*IF(ISNUMBER(SEARCH("semana",I39)),DIAS_SEMANA,1) -> 14 | K39: =IF(ISNUMBER(SEARCH(" a ",I39)),VALUE(MID(I39,FIND(" a ",I39)+3,FIND(" ",I39,FIND(" a ",I39)+3)-FIND(" a ",I39)-3)),VALUE(LEFT(I39,FIND(" ",I39)-1)))*IF(ISNUMBER(SEARCH("semana",I39)),DIAS_SEMANA,1) -> 14 | L39: =(J39+K39)/2 -> 14 | M39: =_xlfn.MINIFS(M40:M$45,E40:E$45,B39) -> 46320 | N39: =_xlfn.MAXIFS(N40:N$45,E40:E$45,B39) -> 46323 | O39: =IF(COUNTIFS(E40:E$45,B39,O40:O$45,"Bloqueado")>0,"Bloqueado",IF(COUNTIFS(E40:E$45,B39,O40:O$45,"Concluído")=COUNTIF(E40:E$45,B39),"Concluído",IF(COUNTIFS(E40:E$45,B39,O40:O$45,"A fazer")=COUNTIF(E40:E$45,B39),"A fazer","Em andamento"))) -> Em andamento | P39: =IF(C39="Story",L39,0) -> 0
B40: ='cronograma-csv'!A35 -> 1501 | C40: ='cronograma-csv'!B35 -> Story | D40: ='cronograma-csv'!C35 -> Executar testes de integração e aceitação | E40: =IF(C40="Epic",B40,IF(C40="Story",'cronograma-csv'!E35,INDEX('cronograma-csv'!$E$2:$E$40,MATCH('cronograma-csv'!F35,'cronograma-csv'!$A$2:$A$40,0)))) -> 1500 | F40: =INDEX($D$7:$D$45,MATCH(E40,$B$7:$B$45,0)) -> Qualidade, publicação e documentação | G40: =IF('cronograma-csv'!G35<>"",'cronograma-csv'!G35,IFERROR(INDEX('cronograma-csv'!$G$2:$G$40,MATCH(B40,'cronograma-csv'!$E$2:$E$40,0)),"—")) -> S06 - Validação e entrega | H40: ='cronograma-csv'!H35 -> Qualidade | I40: ='cronograma-csv'!I35 -> 3 a 4 dias | J40: =VALUE(LEFT(I40,FIND(" ",I40)-1))*IF(ISNUMBER(SEARCH("semana",I40)),DIAS_SEMANA,1) -> 3 | K40: =IF(ISNUMBER(SEARCH(" a ",I40)),VALUE(MID(I40,FIND(" a ",I40)+3,FIND(" ",I40,FIND(" a ",I40)+3)-FIND(" a ",I40)-3)),VALUE(LEFT(I40,FIND(" ",I40)-1)))*IF(ISNUMBER(SEARCH("semana",I40)),DIAS_SEMANA,1) -> 4 | L40: =(J40+K40)/2 -> 3.5 | M40: ='cronograma-csv'!J35 -> 46320 | N40: =M40+MAX(1,ROUNDUP(L40,0))-1 -> 46323 | O40: Em andamento | P40: =IF(C40="Story",L40,0) -> 3.5
B41: ='cronograma-csv'!A36 -> 1502 | C41: ='cronograma-csv'!B36 -> Sub-task | D41: ='cronograma-csv'!C36 -> Tratar erros da API e mensagens ao usuário | E41: =IF(C41="Epic",B41,IF(C41="Story",'cronograma-csv'!E36,INDEX('cronograma-csv'!$E$2:$E$40,MATCH('cronograma-csv'!F36,'cronograma-csv'!$A$2:$A$40,0)))) -> 1500 | F41: =INDEX($D$7:$D$45,MATCH(E41,$B$7:$B$45,0)) -> Qualidade, publicação e documentação | G41: =IF('cronograma-csv'!G36<>"",'cronograma-csv'!G36,IFERROR(INDEX('cronograma-csv'!$G$2:$G$40,MATCH(B41,'cronograma-csv'!$E$2:$E$40,0)),"—")) -> S06 - Validação e entrega | H41: ='cronograma-csv'!H36 -> Frontend | I41: ='cronograma-csv'!I36 -> 1 a 2 dias | J41: =VALUE(LEFT(I41,FIND(" ",I41)-1))*IF(ISNUMBER(SEARCH("semana",I41)),DIAS_SEMANA,1) -> 1 | K41: =IF(ISNUMBER(SEARCH(" a ",I41)),VALUE(MID(I41,FIND(" a ",I41)+3,FIND(" ",I41,FIND(" a ",I41)+3)-FIND(" a ",I41)-3)),VALUE(LEFT(I41,FIND(" ",I41)-1)))*IF(ISNUMBER(SEARCH("semana",I41)),DIAS_SEMANA,1) -> 2 | L41: =(J41+K41)/2 -> 1.5 | M41: ='cronograma-csv'!J36 -> 46321 | N41: =M41+MAX(1,ROUNDUP(L41,0))-1 -> 46322 | O41: Em andamento | P41: =IF(C41="Story",L41,0) -> 0
...

Sheet Scrum
B1: Scrum · Sprints
B2: Esforço em dias (prazo médio das Stories). Os gráficos abaixo leem esta tabela e a aba Calc.
B5: Sprint | C5: Meta (épico) | D5: Início | E5: Fim | F5: Itens | G5: Stories | H5: Planejado (dias) | I5: Concluído (dias) | J5: Em aberto (dias) | K5: % concluído
B6: =Parâmetros!A5 -> S01 - Descoberta e fundação | C6: =INDEX(Cronograma!$F$7:$F$45,MATCH(B6,Cronograma!$G$7:$G$45,0)) -> Produto e arquitetura | D6: =_xlfn.MINIFS(Cronograma!$M$7:$M$45,Cronograma!$G$7:$G$45,B6,Cronograma!$C$7:$C$45,"<>Epic") -> 46296 | E6: =_xlfn.MAXIFS(Cronograma!$N$7:$N$45,Cronograma!$G$7:$G$45,B6,Cronograma!$C$7:$C$45,"<>Epic") -> 46299 | F6: =COUNTIFS(Cronograma!$G$7:$G$45,B6,Cronograma!$C$7:$C$45,"<>Epic") -> 4 | G6: =COUNTIFS(Cronograma!$G$7:$G$45,B6,Cronograma!$C$7:$C$45,"Story") -> 2 | H6: =SUMIFS(Cronograma!$P$7:$P$45,Cronograma!$G$7:$G$45,B6) -> 8 | I6: =SUMIFS(Cronograma!$P$7:$P$45,Cronograma!$G$7:$G$45,B6,Cronograma!$O$7:$O$45,"Concluído") -> 8 | J6: =H6-I6 -> 0 | K6: =IF(H6=0,0,I6/H6) -> 1
B7: =Parâmetros!A6 -> S02 - API e dados | C7: =INDEX(Cronograma!$F$7:$F$45,MATCH(B7,Cronograma!$G$7:$G$45,0)) -> API e persistência de dados | D7: =_xlfn.MINIFS(Cronograma!$M$7:$M$45,Cronograma!$G$7:$G$45,B7,Cronograma!$C$7:$C$45,"<>Epic") -> 46301 | E7: =_xlfn.MAXIFS(Cronograma!$N$7:$N$45,Cronograma!$G$7:$G$45,B7,Cronograma!$C$7:$C$45,"<>Epic") -> 46305 | F7: =COUNTIFS(Cronograma!$G$7:$G$45,B7,Cronograma!$C$7:$C$45,"<>Epic") -> 5 | G7: =COUNTIFS(Cronograma!$G$7:$G$45,B7,Cronograma!$C$7:$C$45,"Story") -> 3 | H7: =SUMIFS(Cronograma!$P$7:$P$45,Cronograma!$G$7:$G$45,B7) -> 12 | I7: =SUMIFS(Cronograma!$P$7:$P$45,Cronograma!$G$7:$G$45,B7,Cronograma!$O$7:$O$45,"Concluído") -> 12 | J7: =H7-I7 -> 0 | K7: =IF(H7=0,0,I7/H7) -> 1
B8: =Parâmetros!A7 -> S03 - Interface e cadastros | C8: =INDEX(Cronograma!$F$7:$F$45,MATCH(B8,Cronograma!$G$7:$G$45,0)) -> Interface e gestão educacional | D8: =_xlfn.MINIFS(Cronograma!$M$7:$M$45,Cronograma!$G$7:$G$45,B8,Cronograma!$C$7:$C$45,"<>Epic") -> 46307 | E8: =_xlfn.MAXIFS(Cronograma!$N$7:$N$45,Cronograma!$G$7:$G$45,B8,Cronograma!$C$7:$C$45,"<>Epic") -> 46311 | F8: =COUNTIFS(Cronograma!$G$7:$G$45,B8,Cronograma!$C$7:$C$45,"<>Epic") -> 6 | G8: =COUNTIFS(Cronograma!$G$7:$G$45,B8,Cronograma!$C$7:$C$45,"Story") -> 3 | H8: =SUMIFS(Cronograma!$P$7:$P$45,Cronograma!$G$7:$G$45,B8) -> 12.5 | I8: =SUMIFS(Cronograma!$P$7:$P$45,Cronograma!$G$7:$G$45,B8,Cronograma!$O$7:$O$45,"Concluído") -> 12.5 | J8: =H8-I8 -> 0 | K8: =IF(H8=0,0,I8/H8) -> 1
B9: =Parâmetros!A8 -> S04 - Avaliações e indicadores | C9: =INDEX(Cronograma!$F$7:$F$45,MATCH(B9,Cronograma!$G$7:$G$45,0)) -> Avaliações e acompanhamento do ODS 4 | D9: =_xlfn.MINIFS(Cronograma!$M$7:$M$45,Cronograma!$G$7:$G$45,B9,Cronograma!$C$7:$C$45,"<>Epic") -> 46312 | E9: =_xlfn.MAXIFS(Cronograma!$N$7:$N$45,Cronograma!$G$7:$G$45,B9,Cronograma!$C$7:$C$45,"<>Epic") -> 46316 | F9: =COUNTIFS(Cronograma!$G$7:$G$45,B9,Cronograma!$C$7:$C$45,"<>Epic") -> 6 | G9: =COUNTIFS(Cronograma!$G$7:$G$45,B9,Cronograma!$C$7:$C$45,"Story") -> 3 | H9: =SUMIFS(Cronograma!$P$7:$P$45,Cronograma!$G$7:$G$45,B9) -> 10.5 | I9: =SUMIFS(Cronograma!$P$7:$P$45,Cronograma!$G$7:$G$45,B9,Cronograma!$O$7:$O$45,"Concluído") -> 10.5 | J9: =H9-I9 -> 0 | K9: =IF(H9=0,0,I9/H9) -> 1
B10: =Parâmetros!A9 -> S05 - Suprimentos e segurança | C10: =INDEX(Cronograma!$F$7:$F$45,MATCH(B10,Cronograma!$G$7:$G$45,0)) -> Suprimentos e controle de acesso | D10: =_xlfn.MINIFS(Cronograma!$M$7:$M$45,Cronograma!$G$7:$G$45,B10,Cronograma!$C$7:$C$45,"<>Epic") -> 46317 | E10: =_xlfn.MAXIFS(Cronograma!$N$7:$N$45,Cronograma!$G$7:$G$45,B10,Cronograma!$C$7:$C$45,"<>Epic") -> 46320 | F10: =COUNTIFS(Cronograma!$G$7:$G$45,B10,Cronograma!$C$7:$C$45,"<>Epic") -> 6 | G10: =COUNTIFS(Cronograma!$G$7:$G$45,B10,Cronograma!$C$7:$C$45,"Story") -> 3 | H10: =SUMIFS(Cronograma!$P$7:$P$45,Cronograma!$G$7:$G$45,B10) -> 11 | I10: =SUMIFS(Cronograma!$P$7:$P$45,Cronograma!$G$7:$G$45,B10,Cronograma!$O$7:$O$45,"Concluído") -> 7.5 | J10: =H10-I10 -> 3.5 | K10: =IF(H10=0,0,I10/H10) -> 0.68181818
B11: =Parâmetros!A10 -> S06 - Validação e entrega | C11: =INDEX(Cronograma!$F$7:$F$45,MATCH(B11,Cronograma!$G$7:$G$45,0)) -> Qualidade, publicação e documentação | D11: =_xlfn.MINIFS(Cronograma!$M$7:$M$45,Cronograma!$G$7:$G$45,B11,Cronograma!$C$7:$C$45,"<>Epic") -> 46320 | E11: =_xlfn.MAXIFS(Cronograma!$N$7:$N$45,Cronograma!$G$7:$G$45,B11,Cronograma!$C$7:$C$45,"<>Epic") -> 46323 | F11: =COUNTIFS(Cronograma!$G$7:$G$45,B11,Cronograma!$C$7:$C$45,"<>Epic") -> 6 | G11: =COUNTIFS(Cronograma!$G$7:$G$45,B11,Cronograma!$C$7:$C$45,"Story") -> 3 | H11: =SUMIFS(Cronograma!$P$7:$P$45,Cronograma!$G$7:$G$45,B11) -> 9 | I11: =SUMIFS(Cronograma!$P$7:$P$45,Cronograma!$G$7:$G$45,B11,Cronograma!$O$7:$O$45,"Concluído") -> 3 | J11: =H11-I11 -> 6 | K11: =IF(H11=0,0,I11/H11) -> 0.33333333
B12: Total | D12: =MIN(D6:D11) -> 46296 | E12: =MAX(E6:E11) -> 46323 | F12: =SUM(F6:F11) -> 33 | G12: =SUM(G6:G11) -> 17 | H12: =SUM(H6:H11) -> 63 | I12: =SUM(I6:I11) -> 53.5 | J12: =SUM(J6:J11) -> 9.5 | K12: =IF(H12=0,0,I12/H12) -> 0.84920635
B14: Velocidade = esforço concluído por sprint. Burndown: restante ideal (linear) x real (escopo menos concluído). A sprint em andamento mostra o parcial até a data de referência.
B16: Gráficos Scrum

Sheet KB
B1: KB · Base de conhecimento
B2: Conteúdo do KB.md organizado por seção. Use o filtro do cabeçalho para pesquisar.
B4: # | C4: Seção | D4: Subseção | E4: Tipo | F4: Conteúdo
B5: 1 | C5: Introdução | E5: Texto | F5: Guia do projeto para quem for mexer nele (pessoas ou o Claude). Resume o que o sistema é, as convenções adotadas, tudo o que foi corrigido e melhorado no trabalho de revisão e o que ainda está em aberto.
B6: 2 | C6: Introdução | E6: Texto | F6: Última atualização: 18/10/2026.
B7: 3 | C7: Introdução | E7: Nota | F7: Como este arquivo foi feito: consolidado a partir das conversas de revisão do projeto. As verificações citadas foram checagem de tipos com bibliotecas simuladas e testes em Node das funções puras. Nada foi testado no navegador pelo Claude, e as telas devem ser conferidas com npm run build e npm run dev. Se um caminho de arquivo aqui divergir do repositório, vale o repositório.
B8: 4 | C8: 1. Visão geral | E8: Texto | F8: Sistema B2B de gestão educacional e venda de materiais escolares, alinhado ao ODS 4 (Educação de Qualidade) da Agenda 2030. É o projeto final do curso da Recode (trilhas.recode.org.br, Turma 2). No menu aparece como Recode — Avaliação Escolas.
B9: 5 | C9: 1. Visão geral | E9: Registro | F9: Frontend: React + TypeScript + Fluent UI v9, nesta pasta.
B10: 6 | C10: 1. Visão geral | E10: Registro | F10: Backend: API REST em Java (Spring Boot), porta 8090, banco PostgreSQL. Fica em outro projeto.
B11: 7 | C11: 1. Visão geral | E11: Registro | F11: Funcionalidades: cadastros (escolas, cursos, alunos, professores, endereços), avaliações (cursos e qualidade), mapa com indicadores socioespaciais, suprimentos (produtos e pedidos), relatório gerencial, Central de Eventos e Auditoria, página do ODS 4, documentação técnica e página de Agradecimentos.
B12: 8 | C12: 1. Visão geral | E12: Registro | F12: Perfis: usuário e administrador (troca pelo menu do avatar na Navbar). Ações de criar, editar e excluir só aparecem para admin.
B13: 9 | C13: 2. Stack e como rodar | E13: Registro | F13: UI — React 19, TypeScript, Fluent UI v9 (@fluentui/react-components, @fluentui/react-icons), Griffel (makeStyles)
B14: 10 | C14: 2. Stack e como rodar | E14: Registro | F14: Build / rota — Vite 8, React Router 7
B15: 11 | C15: 2. Stack e como rodar | E15: Registro | F15: HTTP — Axios (baseURL: '/api'), com interceptores de log
B16: 12 | C16: 2. Stack e como rodar | E16: Registro | F16: Mapa — Google Maps JavaScript API via @vis.gl/react-google-maps
... B46: 42 | C46: 5. Decisões e o porquê | E46: Registro | F46: Perfil na Navbar: um único botão com avatar, papel e menu (MenuItemRadio) no lugar de ícone, texto, switch e avatar soltos.
B47: 43 | C47: 6. Histórico consolidado de correções e melhorias | D47: 6.1 Segurança | E47: Registro | F47: Chave do Google Maps estava escrita no Dashboard.tsx. Passou para VITE_GOOGLE_MAPS_API_KEY no .env.local (no .gitignore), a chave foi trocada e a antiga deve ser desativada.
B48: 44 | C48: 6. Histórico consolidado de correções e melhorias | D48: 6.1 Segurança | E48: Registro | F48: Restringir a chave nova por referenciador HTTP e só às APIs usadas. Conferir o histórico do Git: git log -S "AIza" --oneline.
B49: 45 | C49: 6. Histórico consolidado de correções e melhorias | D49: 6.2 Layout e consistência (todas as telas) | E49: Registro | F49: Título e subtítulo colados (Escolas, Cursos, Professores, ODS 4): resolvido com PageHeader.
B50: 46 | C50: 6. Histórico consolidado de correções e melhorias | D50: 6.2 Layout e consistência (todas as telas) | E50: Registro | F50: Emojis nos títulos trocados por ícones do Fluent; ícone repetido entre Relatório e Central de Eventos corrigido.
B51: 47 | C51: 6. Histórico consolidado de correções e melhorias | D51: 6.2 Layout e consistência (todas as telas) | E51: Registro | F51: KpiCard em Dashboard, Relatório, Central de Eventos e ODS 4.
B52: 48 | C52: 6. Histórico consolidado de correções e melhorias | D52: 6.2 Layout e consistência (todas as telas) | E52: Registro | F52: Badges de tipo de escola fora da família verde/amarelo/vermelho (corTipoEscola).
B53: 49 | C53: 6. Histórico consolidado de correções e melhorias | D53: 6.2 Layout e consistência (todas as telas) | E53: Registro | F53: Avaliações de Qualidade: Stars no lugar do badge, coluna Nota com largura definida e nowrap (as estrelas e o "5/5" invadiam a coluna Data).
B54: 50 | C54: 6. Histórico consolidado de correções e melhorias | D54: 6.2 Layout e consistência (todas as telas) | E54: Registro | F54: Avaliações de Cursos: escola junto do curso; badges de nota de largura igual.
B55: 51 | C55: 6. Histórico consolidado de correções e melhorias | D55: 6.2 Layout e consistência (todas as telas) | E55: Registro | F55: Banners da ODS 4 e Documentação: título e subtítulo em coluna; etiqueta não quebra mais.
B56: 52 | C56: 6. Histórico consolidado de correções e melhorias | D56: 6.2 Layout e consistência (todas as telas) | E56: Registro | F56: Produtos ganhou subtítulo "Catálogo de materiais escolares".
B57: 53 | C57: 6. Histórico consolidado de correções e melhorias | D57: 6.3 Tabelas (11 DataGrids) | E57: Registro | F57: Ordenação por coluna em todas (sortable + compare).
B58: 54 | C58: 6. Histórico consolidado de correções e melhorias | D58: 6.3 Tabelas (11 DataGrids) | E58: Registro | F58: 9 confirm() do navegador trocados por useConfirm (diálogo do Fluent, botão "Excluir" vermelho).
... B94: 90 | C94: 6. Histórico consolidado de correções e melhorias | D94: 6.10 Página de Agradecimentos | E94: Texto | F94: Resumo do sistema, fluxo da arquitetura, tecnologias por grupo, a jornada dos três módulos do curso com "onde aparece no projeto" e uma carta de agradecimento à Recode. Textos em src/data/agradecimentos.ts.
B95: 91 | C95: 7. Casos de referência para testes | E95: Texto | F95: As funções abaixo são puras e foram validadas em Node com os casos listados. Ao criar testes de verdade (sugestão: Vitest), comece por eles.
B96: 92 | C96: 7. Casos de referência para testes | E96: Registro | F96: agregarEscolas: escola de Teresina com 1 aluno urbano a 2,3 km e 11 min → distanciaMedia '2.30', tempoMedio 11, raioMaximoMetros 2300, nota média 4.5 com as notas 4 e 5; aluno ligado por escola.id ou por escolaId; escola sem alunos, endereço ou avaliação não produz NaN; latitude em texto vira número, texto inválido vira null.
B97: 93 | C97: 7. Casos de referência para testes | E97: Registro | F97: calcularKpis: 3 escolas, 4 alunos (2 rurais) → percentualRural '50.0'; média das médias; lista vazia → null e '0.0'.
B98: 94 | C98: 7. Casos de referência para testes | E98: Registro | F98: mediaPorRegiao: sempre 5 regiões; ordenadas por média, sem dado no fim; "Não informado" só aparece se houver escola nele. obterRegiao: PI, piauí, Piaui → Nordeste; XX → Não informado.
B99: 95 | C99: 7. Casos de referência para testes | E99: Registro | F99: mediaPorCurso: nota null não vira zero; escola fora do filtro é ignorada; cursos de mesmo nome usam a escola como rótulo; plural "1 avaliação" / "2 avaliações".
B100: 96 | C100: 7. Casos de referência para testes | E100: Registro | F100: cmpTexto / cmpNumero: ignora acento e caixa, "Escola 2" antes de "Escola 10", vazios no fim.
B101: 97 | C101: 7. Casos de referência para testes | E101: Registro | F101: iniciarCapturaConsole: o console original continua sendo chamado; níveis mapeados; Error, objeto circular e %s formatados; erro do Axios e [vite] ignorados; repetidos viram um; teto por segundo com um aviso; erros da janela e promises rejeitadas; parar() restaura tudo.
B102: 98 | C102: 8. Pendências e ideias | E102: Pendência | F102: Rodar npm run build e passar pelas telas nos temas claro e escuro (nada foi testado no navegador pelo Claude).
B103: 99 | C103: 8. Pendências e ideias | E103: Pendência | F103: Clicar numa barra do Relatório (região ou curso) para filtrar a aba "Escolas".
B104: 100 | C104: 8. Pendências e ideias | E104: Pendência | F104: Incluir a página de Agradecimentos na Documentacao.
B105: 101 | C105: 8. Pendências e ideias | E105: Pendência | F105: Preencher AUTOR em src/data/agradecimentos.ts e personalizar a carta (pessoas e momentos específicos do curso).
...

Sheet Pesquisas
B1: Pesquisas
B2: Registro de pesquisas e investigações do projeto. Preencha as células amarelas, uma linha por pesquisa.
B3: Status: Em aberto, Em pesquisa ou Concluída. Link ou nome da fonte ajuda a reencontrar a informação depois.
B5: Data | C5: Tema | D5: Pergunta | E5: Resultado / conclusão | F5: Fonte ou link | G5: Status
B6: 46321 | C6: n8n em produção | D6: Por que o módulo N8N falha em produção? | E6: A investigar. A entrega do módulo fica em aberto. | G6: Em aberto

Sheet Calc
A1: Ponto | B1: Ideal | C1: Real | D1: Escopo | E1: Entregue acum. | G1: Sprint | H1: A fazer | I1: Em andamento | J1: Concluído | K1: Bloqueado | M1: Componente | N1: A fazer | O1: Em andamento | P1: Concluído | Q1: Bloqueado
A2: Início | B2: =Scrum!$H$12 -> 63 | C2: =Scrum!$H$12 -> 63 | D2: =Scrum!$H$12 -> 63 | E2: 0 | G2: =LEFT(Scrum!B6,3) -> S01 | H2: =COUNTIFS(Cronograma!$G$7:$G$45,Scrum!$B6,Cronograma!$C$7:$C$45,"<>Epic",Cronograma!$O$7:$O$45,H$1) -> 0 | I2: =COUNTIFS(Cronograma!$G$7:$G$45,Scrum!$B6,Cronograma!$C$7:$C$45,"<>Epic",Cronograma!$O$7:$O$45,I$1) -> 0 | J2: =COUNTIFS(Cronograma!$G$7:$G$45,Scrum!$B6,Cronograma!$C$7:$C$45,"<>Epic",Cronograma!$O$7:$O$45,J$1) -> 4 | K2: =COUNTIFS(Cronograma!$G$7:$G$45,Scrum!$B6,Cronograma!$C$7:$C$45,"<>Epic",Cronograma!$O$7:$O$45,K$1) -> 0 | M2: =Parâmetros!C5 -> Produto | N2: =COUNTIFS(Cronograma!$H$7:$H$45,$M2,Cronograma!$C$7:$C$45,"<>Epic",Cronograma!$O$7:$O$45,N$1) -> 0 | O2: =COUNTIFS(Cronograma!$H$7:$H$45,$M2,Cronograma!$C$7:$C$45,"<>Epic",Cronograma!$O$7:$O$45,O$1) -> 0 | P2: =COUNTIFS(Cronograma!$H$7:$H$45,$M2,Cronograma!$C$7:$C$45,"<>Epic",Cronograma!$O$7:$O$45,P$1) -> 2 | Q2: =COUNTIFS(Cronograma!$H$7:$H$45,$M2,Cronograma!$C$7:$C$45,"<>Epic",Cronograma!$O$7:$O$45,Q$1) -> 0
A3: =LEFT(Scrum!B6,3) -> S01 | B3: =Scrum!$H$12*(1-ROWS(A$3:A3)/COUNTA(Scrum!$B$6:$B$11)) -> 52.5 | C3: =C2-Scrum!I6 -> 55 | D3: =Scrum!$H$12 -> 63 | E3: =E2+Scrum!I6 -> 8 | G3: =LEFT(Scrum!B7,3) -> S02 | H3: =COUNTIFS(Cronograma!$G$7:$G$45,Scrum!$B7,Cronograma!$C$7:$C$45,"<>Epic",Cronograma!$O$7:$O$45,H$1) -> 0 | I3: =COUNTIFS(Cronograma!$G$7:$G$45,Scrum!$B7,Cronograma!$C$7:$C$45,"<>Epic",Cronograma!$O$7:$O$45,I$1) -> 0 | J3: =COUNTIFS(Cronograma!$G$7:$G$45,Scrum!$B7,Cronograma!$C$7:$C$45,"<>Epic",Cronograma!$O$7:$O$45,J$1) -> 5 | K3: =COUNTIFS(Cronograma!$G$7:$G$45,Scrum!$B7,Cronograma!$C$7:$C$45,"<>Epic",Cronograma!$O$7:$O$45,K$1) -> 0 | M3: =Parâmetros!C6 -> Arquitetura | N3: =COUNTIFS(Cronograma!$H$7:$H$45,$M3,Cronograma!$C$7:$C$45,"<>Epic",Cronograma!$O$7:$O$45,N$1) -> 0 | O3: =COUNTIFS(Cronograma!$H$7:$H$45,$M3,Cronograma!$C$7:$C$45,"<>Epic",Cronograma!$O$7:$O$45,O$1) -> 0 | P3: =COUNTIFS(Cronograma!$H$7:$H$45,$M3,Cronograma!$C$7:$C$45,"<>Epic",Cronograma!$O$7:$O$45,P$1) -> 1 | Q3: =COUNTIFS(Cronograma!$H$7:$H$45,$M3,Cronograma!$C$7:$C$45,"<>Epic",Cronograma!$O$7:$O$45,Q$1) -> 0
