Workbook
Name Q_BOA: 'Parâmetros'!$E$5
Name Q_ATENCAO: 'Parâmetros'!$E$6
Name C_BOA: 'Parâmetros'!$E$7
Name C_ATENCAO: 'Parâmetros'!$E$8
Name MIN_AMOSTRA: 'Parâmetros'!$E$9

Sheet Visão Geral
B1: 4 | C1: Objetivo de Desenvolvimento Sustentável 4 · Agenda 2030 da ONU
C2: Educação de Qualidade
C3: Recode — Avaliação Escolas: indicadores lidos das APIs públicas. Use Dados → Atualizar Tudo para atualizar.
B4: Escolas cadastradas | E4: Escolas avaliadas | H4: KPI · Média das avaliações de qualidade | K4: KPI · Média das avaliações dos cursos
B5: =ROWS(escolas[Column1.id]) | E5: =COUNT(avaliacoes_qualidade[Nota média]) | H5: =IFERROR(AVERAGE(avaliacoes_qualidade[Nota média]),"—") | K5: =IFERROR(AVERAGE(avaliacoes_cursos[Nota média]),"—")
B7: ="todas as dependências administrativas" | E7: ="de "&ROWS(escolas[Column1.id])&" cadastradas ("&TEXT(COUNT(avaliacoes_qualidade[Nota média])/ROWS(escolas[Column1.id]),"0%")&")" | H7: ="Faixa: "&IF(ISNUMBER(H5),IF(H5>=Q_BOA,"Boa",IF(H5>=Q_ATENCAO,"Atenção","Crítica")),"—") | K7: ="Faixa: "&IF(ISNUMBER(K5),IF(K5>=C_BOA,"Boa",IF(K5>=C_ATENCAO,"Atenção","Crítica")),"—")
B9: Total de avaliações de qualidade | E9: Escolas com nota boa | H9: Professores cadastrados | K9: Cursos avaliados
B10: =SUM(avaliacoes_qualidade[Avaliações]) | E10: =IFERROR(COUNTIF(avaliacoes_qualidade[Nota média],">="&Q_BOA)/COUNT(avaliacoes_qualidade[Nota média]),"—") | H10: =ROWS(professores[Column1.id]) | K10: =COUNT(avaliacoes_cursos[Nota média])
B12: ="notas registradas nas escolas" | E12: ="nota de "&Q_BOA&" ou mais, entre as avaliadas" | H12: ="corpo docente da rede" | K12: ="de "&ROWS(cursos[id])&" cursos cadastrados"
B35: Destaques
B36: Indicador | E36: Nome | J36: Nota | K36: Observação
B37: Maior nota de escola | E37: =INDEX(Calc!$B$2:$B$301,MATCH(MAX(Calc!$C$2:$C$301),Calc!$C$2:$C$301,0)) | J37: =MAX(Calc!$C$2:$C$301) | K37: =COUNTIF(Calc!$C$2:$C$301,MAX(Calc!$C$2:$C$301))&" escola(s) com esta nota"
B38: Menor nota de escola | E38: =INDEX(Calc!$B$2:$B$301,MATCH(MIN(Calc!$C$2:$C$301),Calc!$C$2:$C$301,0)) | J38: =MIN(Calc!$C$2:$C$301) | K38: =COUNTIF(Calc!$C$2:$C$301,MIN(Calc!$C$2:$C$301))&" escola(s) com esta nota"
B39: Maior nota de curso | E39: =INDEX(Calc!$Q$2:$Q$301,MATCH(MAX(Calc!$P$2:$P$301),Calc!$P$2:$P$301,0)) | J39: =MAX(Calc!$P$2:$P$301) | K39: =COUNTIF(Calc!$P$2:$P$301,MAX(Calc!$P$2:$P$301))&" curso(s) com esta nota"
B40: Menor nota de curso | E40: =INDEX(Calc!$Q$2:$Q$301,MATCH(MIN(Calc!$P$2:$P$301),Calc!$P$2:$P$301,0)) | J40: =MIN(Calc!$P$2:$P$301) | K40: =COUNTIF(Calc!$P$2:$P$301,MIN(Calc!$P$2:$P$301))&" curso(s) com esta nota"
B42: Quando várias escolas empatam na nota, o destaque mostra a primeira da lista.

Sheet Por Região
B1: 4 | C1: ODS 4 · Educação de Qualidade · Recode — Avaliação Escolas
C2: Avaliação por Região
C3: Média das notas de qualidade das escolas avaliadas, por região (escala 1 a 5).
B4: Região | C4: Escolas avaliadas | D4: Média (1–5) | E4: Faixa | F4: Observação | H4: Média geral
B5: Norte | C5: =COUNTIFS(Calc!$H$2:$H$301,B5,Calc!$C$2:$C$301,">=0") | D5: =IFERROR(AVERAGEIFS(Calc!$C$2:$C$301,Calc!$H$2:$H$301,B5),0) | E5: =IF(C5=0,"—",IF(D5>=Q_BOA,"Boa",IF(D5>=Q_ATENCAO,"Atenção","Crítica"))) | F5: =IF(C5=0,"sem avaliações",IF(C5<MIN_AMOSTRA,"amostra pequena","ok")) | H5: =IFERROR(AVERAGE(avaliacoes_qualidade[Nota média]),0)
B6: Nordeste | C6: =COUNTIFS(Calc!$H$2:$H$301,B6,Calc!$C$2:$C$301,">=0") | D6: =IFERROR(AVERAGEIFS(Calc!$C$2:$C$301,Calc!$H$2:$H$301,B6),0) | E6: =IF(C6=0,"—",IF(D6>=Q_BOA,"Boa",IF(D6>=Q_ATENCAO,"Atenção","Crítica"))) | F6: =IF(C6=0,"sem avaliações",IF(C6<MIN_AMOSTRA,"amostra pequena","ok")) | H6: =IFERROR(AVERAGE(avaliacoes_qualidade[Nota média]),0)
B7: Centro-Oeste | C7: =COUNTIFS(Calc!$H$2:$H$301,B7,Calc!$C$2:$C$301,">=0") | D7: =IFERROR(AVERAGEIFS(Calc!$C$2:$C$301,Calc!$H$2:$H$301,B7),0) | E7: =IF(C7=0,"—",IF(D7>=Q_BOA,"Boa",IF(D7>=Q_ATENCAO,"Atenção","Crítica"))) | F7: =IF(C7=0,"sem avaliações",IF(C7<MIN_AMOSTRA,"amostra pequena","ok")) | H7: =IFERROR(AVERAGE(avaliacoes_qualidade[Nota média]),0)
B8: Sudeste | C8: =COUNTIFS(Calc!$H$2:$H$301,B8,Calc!$C$2:$C$301,">=0") | D8: =IFERROR(AVERAGEIFS(Calc!$C$2:$C$301,Calc!$H$2:$H$301,B8),0) | E8: =IF(C8=0,"—",IF(D8>=Q_BOA,"Boa",IF(D8>=Q_ATENCAO,"Atenção","Crítica"))) | F8: =IF(C8=0,"sem avaliações",IF(C8<MIN_AMOSTRA,"amostra pequena","ok")) | H8: =IFERROR(AVERAGE(avaliacoes_qualidade[Nota média]),0)
B9: Sul | C9: =COUNTIFS(Calc!$H$2:$H$301,B9,Calc!$C$2:$C$301,">=0") | D9: =IFERROR(AVERAGEIFS(Calc!$C$2:$C$301,Calc!$H$2:$H$301,B9),0) | E9: =IF(C9=0,"—",IF(D9>=Q_BOA,"Boa",IF(D9>=Q_ATENCAO,"Atenção","Crítica"))) | F9: =IF(C9=0,"sem avaliações",IF(C9<MIN_AMOSTRA,"amostra pequena","ok")) | H9: =IFERROR(AVERAGE(avaliacoes_qualidade[Nota média]),0)
B10: Não localizada | C10: =COUNTIFS(Calc!$H$2:$H$301,B10,Calc!$C$2:$C$301,">=0") | D10: =IFERROR(AVERAGEIFS(Calc!$C$2:$C$301,Calc!$H$2:$H$301,B10),0) | E10: =IF(C10=0,"—",IF(D10>=Q_BOA,"Boa",IF(D10>=Q_ATENCAO,"Atenção","Crítica"))) | F10: =IF(C10=0,"sem avaliações",IF(C10<MIN_AMOSTRA,"amostra pequena","ok")) | H10: =IFERROR(AVERAGE(avaliacoes_qualidade[Nota média]),0)
B12: Regiões com poucas escolas avaliadas têm amostra pequena: leia com cautela. "Não localizada" = escola cujo nome não casa com nenhuma cidade da tabela de endereços.

Sheet Avaliação Cursos
B1: 4 | C1: ODS 4 · Educação de Qualidade · Recode — Avaliação Escolas
C2: Avaliação dos Cursos
C3: Média das avaliações por curso (escala 0 a 10). Escolha a ordem na célula em azul claro.
B4: Ordem | C4: Maiores notas primeiro | F4: ="Cursos avaliados: "&COUNT(Calc!$P$2:$P$301)&" · média geral: "&TEXT(AVERAGE(Calc!$P$2:$P$301),"0.0")
B6: # | C6: Curso | D6: Escola | E6: Nota | F6: Faixa
B7: =IF(1<=COUNT(Calc!$R$2:$R$301),1,"") | C7: =IF(B7="","",INDEX(Calc!$Q$2:$Q$301,I7)) | D7: =IF(B7="","",INDEX(Calc!$O$2:$O$301,I7)) | E7: =IF(B7="","",INDEX(Calc!$P$2:$P$301,I7)) | F7: =IF(E7="","",IF(E7>=C_BOA,"Boa",IF(E7>=C_ATENCAO,"Atenção","Crítica"))) | H7: =IF(B7="","",IF($C$4="Maiores notas primeiro",LARGE(Calc!$R$2:$R$301,B7),SMALL(Calc!$R$2:$R$301,B7))) | I7: =IF(B7="","",MATCH(H7,Calc!$R$2:$R$301,0))
B8: =IF(2<=COUNT(Calc!$R$2:$R$301),2,"") | C8: =IF(B8="","",INDEX(Calc!$Q$2:$Q$301,I8)) | D8: =IF(B8="","",INDEX(Calc!$O$2:$O$301,I8)) | E8: =IF(B8="","",INDEX(Calc!$P$2:$P$301,I8)) | F8: =IF(E8="","",IF(E8>=C_BOA,"Boa",IF(E8>=C_ATENCAO,"Atenção","Crítica"))) | H8: =IF(B8="","",IF($C$4="Maiores notas primeiro",LARGE(Calc!$R$2:$R$301,B8),SMALL(Calc!$R$2:$R$301,B8))) | I8: =IF(B8="","",MATCH(H8,Calc!$R$2:$R$301,0))
B9: =IF(3<=COUNT(Calc!$R$2:$R$301),3,"") | C9: =IF(B9="","",INDEX(Calc!$Q$2:$Q$301,I9)) | D9: =IF(B9="","",INDEX(Calc!$O$2:$O$301,I9)) | E9: =IF(B9="","",INDEX(Calc!$P$2:$P$301,I9)) | F9: =IF(E9="","",IF(E9>=C_BOA,"Boa",IF(E9>=C_ATENCAO,"Atenção","Crítica"))) | H9: =IF(B9="","",IF($C$4="Maiores notas primeiro",LARGE(Calc!$R$2:$R$301,B9),SMALL(Calc!$R$2:$R$301,B9))) | I9: =IF(B9="","",MATCH(H9,Calc!$R$2:$R$301,0))
B10: =IF(4<=COUNT(Calc!$R$2:$R$301),4,"") | C10: =IF(B10="","",INDEX(Calc!$Q$2:$Q$301,I10)) | D10: =IF(B10="","",INDEX(Calc!$O$2:$O$301,I10)) | E10: =IF(B10="","",INDEX(Calc!$P$2:$P$301,I10)) | F10: =IF(E10="","",IF(E10>=C_BOA,"Boa",IF(E10>=C_ATENCAO,"Atenção","Crítica"))) | H10: =IF(B10="","",IF($C$4="Maiores notas primeiro",LARGE(Calc!$R$2:$R$301,B10),SMALL(Calc!$R$2:$R$301,B10))) | I10: =IF(B10="","",MATCH(H10,Calc!$R$2:$R$301,0))
B11: =IF(5<=COUNT(Calc!$R$2:$R$301),5,"") | C11: =IF(B11="","",INDEX(Calc!$Q$2:$Q$301,I11)) | D11: =IF(B11="","",INDEX(Calc!$O$2:$O$301,I11)) | E11: =IF(B11="","",INDEX(Calc!$P$2:$P$301,I11)) | F11: =IF(E11="","",IF(E11>=C_BOA,"Boa",IF(E11>=C_ATENCAO,"Atenção","Crítica"))) | H11: =IF(B11="","",IF($C$4="Maiores notas primeiro",LARGE(Calc!$R$2:$R$301,B11),SMALL(Calc!$R$2:$R$301,B11))) | I11: =IF(B11="","",MATCH(H11,Calc!$R$2:$R$301,0))
B12: =IF(6<=COUNT(Calc!$R$2:$R$301),6,"") | C12: =IF(B12="","",INDEX(Calc!$Q$2:$Q$301,I12)) | D12: =IF(B12="","",INDEX(Calc!$O$2:$O$301,I12)) | E12: =IF(B12="","",INDEX(Calc!$P$2:$P$301,I12)) | F12: =IF(E12="","",IF(E12>=C_BOA,"Boa",IF(E12>=C_ATENCAO,"Atenção","Crítica"))) | H12: =IF(B12="","",IF($C$4="Maiores notas primeiro",LARGE(Calc!$R$2:$R$301,B12),SMALL(Calc!$R$2:$R$301,B12))) | I12: =IF(B12="","",MATCH(H12,Calc!$R$2:$R$301,0))
B13: =IF(7<=COUNT(Calc!$R$2:$R$301),7,"") | C13: =IF(B13="","",INDEX(Calc!$Q$2:$Q$301,I13)) | D13: =IF(B13="","",INDEX(Calc!$O$2:$O$301,I13)) | E13: =IF(B13="","",INDEX(Calc!$P$2:$P$301,I13)) | F13: =IF(E13="","",IF(E13>=C_BOA,"Boa",IF(E13>=C_ATENCAO,"Atenção","Crítica"))) | H13: =IF(B13="","",IF($C$4="Maiores notas primeiro",LARGE(Calc!$R$2:$R$301,B13),SMALL(Calc!$R$2:$R$301,B13))) | I13: =IF(B13="","",MATCH(H13,Calc!$R$2:$R$301,0))
B14: =IF(8<=COUNT(Calc!$R$2:$R$301),8,"") | C14: =IF(B14="","",INDEX(Calc!$Q$2:$Q$301,I14)) | D14: =IF(B14="","",INDEX(Calc!$O$2:$O$301,I14)) | E14: =IF(B14="","",INDEX(Calc!$P$2:$P$301,I14)) | F14: =IF(E14="","",IF(E14>=C_BOA,"Boa",IF(E14>=C_ATENCAO,"Atenção","Crítica"))) | H14: =IF(B14="","",IF($C$4="Maiores notas primeiro",LARGE(Calc!$R$2:$R$301,B14),SMALL(Calc!$R$2:$R$301,B14))) | I14: =IF(B14="","",MATCH(H14,Calc!$R$2:$R$301,0))
B15: =IF(9<=COUNT(Calc!$R$2:$R$301),9,"") | C15: =IF(B15="","",INDEX(Calc!$Q$2:$Q$301,I15)) | D15: =IF(B15="","",INDEX(Calc!$O$2:$O$301,I15)) | E15: =IF(B15="","",INDEX(Calc!$P$2:$P$301,I15)) | F15: =IF(E15="","",IF(E15>=C_BOA,"Boa",IF(E15>=C_ATENCAO,"Atenção","Crítica"))) | H15: =IF(B15="","",IF($C$4="Maiores notas primeiro",LARGE(Calc!$R$2:$R$301,B15),SMALL(Calc!$R$2:$R$301,B15))) | I15: =IF(B15="","",MATCH(H15,Calc!$R$2:$R$301,0))
B16: =IF(10<=COUNT(Calc!$R$2:$R$301),10,"") | C16: =IF(B16="","",INDEX(Calc!$Q$2:$Q$301,I16)) | D16: =IF(B16="","",INDEX(Calc!$O$2:$O$301,I16)) | E16: =IF(B16="","",INDEX(Calc!$P$2:$P$301,I16)) | F16: =IF(E16="","",IF(E16>=C_BOA,"Boa",IF(E16>=C_ATENCAO,"Atenção","Crítica"))) | H16: =IF(B16="","",IF($C$4="Maiores notas primeiro",LARGE(Calc!$R$2:$R$301,B16),SMALL(Calc!$R$2:$R$301,B16))) | I16: =IF(B16="","",MATCH(H16,Calc!$R$2:$R$301,0))
B17: =IF(11<=COUNT(Calc!$R$2:$R$301),11,"") | C17: =IF(B17="","",INDEX(Calc!$Q$2:$Q$301,I17)) | D17: =IF(B17="","",INDEX(Calc!$O$2:$O$301,I17)) | E17: =IF(B17="","",INDEX(Calc!$P$2:$P$301,I17)) | F17: =IF(E17="","",IF(E17>=C_BOA,"Boa",IF(E17>=C_ATENCAO,"Atenção","Crítica"))) | H17: =IF(B17="","",IF($C$4="Maiores notas primeiro",LARGE(Calc!$R$2:$R$301,B17),SMALL(Calc!$R$2:$R$301,B17))) | I17: =IF(B17="","",MATCH(H17,Calc!$R$2:$R$301,0))
B18: =IF(12<=COUNT(Calc!$R$2:$R$301),12,"") | C18: =IF(B18="","",INDEX(Calc!$Q$2:$Q$301,I18)) | D18: =IF(B18="","",INDEX(Calc!$O$2:$O$301,I18)) | E18: =IF(B18="","",INDEX(Calc!$P$2:$P$301,I18)) | F18: =IF(E18="","",IF(E18>=C_BOA,"Boa",IF(E18>=C_ATENCAO,"Atenção","Crítica"))) | H18: =IF(B18="","",IF($C$4="Maiores notas primeiro",LARGE(Calc!$R$2:$R$301,B18),SMALL(Calc!$R$2:$R$301,B18))) | I18: =IF(B18="","",MATCH(H18,Calc!$R$2:$R$301,0))
B19: =IF(13<=COUNT(Calc!$R$2:$R$301),13,"") | C19: =IF(B19="","",INDEX(Calc!$Q$2:$Q$301,I19)) | D19: =IF(B19="","",INDEX(Calc!$O$2:$O$301,I19)) | E19: =IF(B19="","",INDEX(Calc!$P$2:$P$301,I19)) | F19: =IF(E19="","",IF(E19>=C_BOA,"Boa",IF(E19>=C_ATENCAO,"Atenção","Crítica"))) | H19: =IF(B19="","",IF($C$4="Maiores notas primeiro",LARGE(Calc!$R$2:$R$301,B19),SMALL(Calc!$R$2:$R$301,B19))) | I19: =IF(B19="","",MATCH(H19,Calc!$R$2:$R$301,0))
B20: =IF(14<=COUNT(Calc!$R$2:$R$301),14,"") | C20: =IF(B20="","",INDEX(Calc!$Q$2:$Q$301,I20)) | D20: =IF(B20="","",INDEX(Calc!$O$2:$O$301,I20)) | E20: =IF(B20="","",INDEX(Calc!$P$2:$P$301,I20)) | F20: =IF(E20="","",IF(E20>=C_BOA,"Boa",IF(E20>=C_ATENCAO,"Atenção","Crítica"))) | H20: =IF(B20="","",IF($C$4="Maiores notas primeiro",LARGE(Calc!$R$2:$R$301,B20),SMALL(Calc!$R$2:$R$301,B20))) | I20: =IF(B20="","",MATCH(H20,Calc!$R$2:$R$301,0))
B21: =IF(15<=COUNT(Calc!$R$2:$R$301),15,"") | C21: =IF(B21="","",INDEX(Calc!$Q$2:$Q$301,I21)) | D21: =IF(B21="","",INDEX(Calc!$O$2:$O$301,I21)) | E21: =IF(B21="","",INDEX(Calc!$P$2:$P$301,I21)) | F21: =IF(E21="","",IF(E21>=C_BOA,"Boa",IF(E21>=C_ATENCAO,"Atenção","Crítica"))) | H21: =IF(B21="","",IF($C$4="Maiores notas primeiro",LARGE(Calc!$R$2:$R$301,B21),SMALL(Calc!$R$2:$R$301,B21))) | I21: =IF(B21="","",MATCH(H21,Calc!$R$2:$R$301,0))
B22: =IF(16<=COUNT(Calc!$R$2:$R$301),16,"") | C22: =IF(B22="","",INDEX(Calc!$Q$2:$Q$301,I22)) | D22: =IF(B22="","",INDEX(Calc!$O$2:$O$301,I22)) | E22: =IF(B22="","",INDEX(Calc!$P$2:$P$301,I22)) | F22: =IF(E22="","",IF(E22>=C_BOA,"Boa",IF(E22>=C_ATENCAO,"Atenção","Crítica"))) | H22: =IF(B22="","",IF($C$4="Maiores notas primeiro",LARGE(Calc!$R$2:$R$301,B22),SMALL(Calc!$R$2:$R$301,B22))) | I22: =IF(B22="","",MATCH(H22,Calc!$R$2:$R$301,0))
B23: =IF(17<=COUNT(Calc!$R$2:$R$301),17,"") | C23: =IF(B23="","",INDEX(Calc!$Q$2:$Q$301,I23)) | D23: =IF(B23="","",INDEX(Calc!$O$2:$O$301,I23)) | E23: =IF(B23="","",INDEX(Calc!$P$2:$P$301,I23)) | F23: =IF(E23="","",IF(E23>=C_BOA,"Boa",IF(E23>=C_ATENCAO,"Atenção","Crítica"))) | H23: =IF(B23="","",IF($C$4="Maiores notas primeiro",LARGE(Calc!$R$2:$R$301,B23),SMALL(Calc!$R$2:$R$301,B23))) | I23: =IF(B23="","",MATCH(H23,Calc!$R$2:$R$301,0))
B24: =IF(18<=COUNT(Calc!$R$2:$R$301),18,"") | C24: =IF(B24="","",INDEX(Calc!$Q$2:$Q$301,I24)) | D24: =IF(B24="","",INDEX(Calc!$O$2:$O$301,I24)) | E24: =IF(B24="","",INDEX(Calc!$P$2:$P$301,I24)) | F24: =IF(E24="","",IF(E24>=C_BOA,"Boa",IF(E24>=C_ATENCAO,"Atenção","Crítica"))) | H24: =IF(B24="","",IF($C$4="Maiores notas primeiro",LARGE(Calc!$R$2:$R$301,B24),SMALL(Calc!$R$2:$R$301,B24))) | I24: =IF(B24="","",MATCH(H24,Calc!$R$2:$R$301,0))
B25: =IF(19<=COUNT(Calc!$R$2:$R$301),19,"") | C25: =IF(B25="","",INDEX(Calc!$Q$2:$Q$301,I25)) | D25: =IF(B25="","",INDEX(Calc!$O$2:$O$301,I25)) | E25: =IF(B25="","",INDEX(Calc!$P$2:$P$301,I25)) | F25: =IF(E25="","",IF(E25>=C_BOA,"Boa",IF(E25>=C_ATENCAO,"Atenção","Crítica"))) | H25: =IF(B25="","",IF($C$4="Maiores notas primeiro",LARGE(Calc!$R$2:$R$301,B25),SMALL(Calc!$R$2:$R$301,B25))) | I25: =IF(B25="","",MATCH(H25,Calc!$R$2:$R$301,0))
B26: =IF(20<=COUNT(Calc!$R$2:$R$301),20,"") | C26: =IF(B26="","",INDEX(Calc!$Q$2:$Q$301,I26)) | D26: =IF(B26="","",INDEX(Calc!$O$2:$O$301,I26)) | E26: =IF(B26="","",INDEX(Calc!$P$2:$P$301,I26)) | F26: =IF(E26="","",IF(E26>=C_BOA,"Boa",IF(E26>=C_ATENCAO,"Atenção","Crítica"))) | H26: =IF(B26="","",IF($C$4="Maiores notas primeiro",LARGE(Calc!$R$2:$R$301,B26),SMALL(Calc!$R$2:$R$301,B26))) | I26: =IF(B26="","",MATCH(H26,Calc!$R$2:$R$301,0))
B27: =IF(21<=COUNT(Calc!$R$2:$R$301),21,"") | C27: =IF(B27="","",INDEX(Calc!$Q$2:$Q$301,I27)) | D27: =IF(B27="","",INDEX(Calc!$O$2:$O$301,I27)) | E27: =IF(B27="","",INDEX(Calc!$P$2:$P$301,I27)) | F27: =IF(E27="","",IF(E27>=C_BOA,"Boa",IF(E27>=C_ATENCAO,"Atenção","Crítica"))) | H27: =IF(B27="","",IF($C$4="Maiores notas primeiro",LARGE(Calc!$R$2:$R$301,B27),SMALL(Calc!$R$2:$R$301,B27))) | I27: =IF(B27="","",MATCH(H27,Calc!$R$2:$R$301,0))
B28: =IF(22<=COUNT(Calc!$R$2:$R$301),22,"") | C28: =IF(B28="","",INDEX(Calc!$Q$2:$Q$301,I28)) | D28: =IF(B28="","",INDEX(Calc!$O$2:$O$301,I28)) | E28: =IF(B28="","",INDEX(Calc!$P$2:$P$301,I28)) | F28: =IF(E28="","",IF(E28>=C_BOA,"Boa",IF(E28>=C_ATENCAO,"Atenção","Crítica"))) | H28: =IF(B28="","",IF($C$4="Maiores notas primeiro",LARGE(Calc!$R$2:$R$301,B28),SMALL(Calc!$R$2:$R$301,B28))) | I28: =IF(B28="","",MATCH(H28,Calc!$R$2:$R$301,0))
B29: =IF(23<=COUNT(Calc!$R$2:$R$301),23,"") | C29: =IF(B29="","",INDEX(Calc!$Q$2:$Q$301,I29)) | D29: =IF(B29="","",INDEX(Calc!$O$2:$O$301,I29)) | E29: =IF(B29="","",INDEX(Calc!$P$2:$P$301,I29)) | F29: =IF(E29="","",IF(E29>=C_BOA,"Boa",IF(E29>=C_ATENCAO,"Atenção","Crítica"))) | H29: =IF(B29="","",IF($C$4="Maiores notas primeiro",LARGE(Calc!$R$2:$R$301,B29),SMALL(Calc!$R$2:$R$301,B29))) | I29: =IF(B29="","",MATCH(H29,Calc!$R$2:$R$301,0))
B30: =IF(24<=COUNT(Calc!$R$2:$R$301),24,"") | C30: =IF(B30="","",INDEX(Calc!$Q$2:$Q$301,I30)) | D30: =IF(B30="","",INDEX(Calc!$O$2:$O$301,I30)) | E30: =IF(B30="","",INDEX(Calc!$P$2:$P$301,I30)) | F30: =IF(E30="","",IF(E30>=C_BOA,"Boa",IF(E30>=C_ATENCAO,"Atenção","Crítica"))) | H30: =IF(B30="","",IF($C$4="Maiores notas primeiro",LARGE(Calc!$R$2:$R$301,B30),SMALL(Calc!$R$2:$R$301,B30))) | I30: =IF(B30="","",MATCH(H30,Calc!$R$2:$R$301,0))
B31: =IF(25<=COUNT(Calc!$R$2:$R$301),25,"") | C31: =IF(B31="","",INDEX(Calc!$Q$2:$Q$301,I31)) | D31: =IF(B31="","",INDEX(Calc!$O$2:$O$301,I31)) | E31: =IF(B31="","",INDEX(Calc!$P$2:$P$301,I31)) | F31: =IF(E31="","",IF(E31>=C_BOA,"Boa",IF(E31>=C_ATENCAO,"Atenção","Crítica"))) | H31: =IF(B31="","",IF($C$4="Maiores notas primeiro",LARGE(Calc!$R$2:$R$301,B31),SMALL(Calc!$R$2:$R$301,B31))) | I31: =IF(B31="","",MATCH(H31,Calc!$R$2:$R$301,0))
B32: =IF(26<=COUNT(Calc!$R$2:$R$301),26,"") | C32: =IF(B32="","",INDEX(Calc!$Q$2:$Q$301,I32)) | D32: =IF(B32="","",INDEX(Calc!$O$2:$O$301,I32)) | E32: =IF(B32="","",INDEX(Calc!$P$2:$P$301,I32)) | F32: =IF(E32="","",IF(E32>=C_BOA,"Boa",IF(E32>=C_ATENCAO,"Atenção","Crítica"))) | H32: =IF(B32="","",IF($C$4="Maiores notas primeiro",LARGE(Calc!$R$2:$R$301,B32),SMALL(Calc!$R$2:$R$301,B32))) | I32: =IF(B32="","",MATCH(H32,Calc!$R$2:$R$301,0))
B33: =IF(27<=COUNT(Calc!$R$2:$R$301),27,"") | C33: =IF(B33="","",INDEX(Calc!$Q$2:$Q$301,I33)) | D33: =IF(B33="","",INDEX(Calc!$O$2:$O$301,I33)) | E33: =IF(B33="","",INDEX(Calc!$P$2:$P$301,I33)) | F33: =IF(E33="","",IF(E33>=C_BOA,"Boa",IF(E33>=C_ATENCAO,"Atenção","Crítica"))) | H33: =IF(B33="","",IF($C$4="Maiores notas primeiro",LARGE(Calc!$R$2:$R$301,B33),SMALL(Calc!$R$2:$R$301,B33))) | I33: =IF(B33="","",MATCH(H33,Calc!$R$2:$R$301,0))
B34: =IF(28<=COUNT(Calc!$R$2:$R$301),28,"") | C34: =IF(B34="","",INDEX(Calc!$Q$2:$Q$301,I34)) | D34: =IF(B34="","",INDEX(Calc!$O$2:$O$301,I34)) | E34: =IF(B34="","",INDEX(Calc!$P$2:$P$301,I34)) | F34: =IF(E34="","",IF(E34>=C_BOA,"Boa",IF(E34>=C_ATENCAO,"Atenção","Crítica"))) | H34: =IF(B34="","",IF($C$4="Maiores notas primeiro",LARGE(Calc!$R$2:$R$301,B34),SMALL(Calc!$R$2:$R$301,B34))) | I34: =IF(B34="","",MATCH(H34,Calc!$R$2:$R$301,0))
B35: =IF(29<=COUNT(Calc!$R$2:$R$301),29,"") | C35: =IF(B35="","",INDEX(Calc!$Q$2:$Q$301,I35)) | D35: =IF(B35="","",INDEX(Calc!$O$2:$O$301,I35)) | E35: =IF(B35="","",INDEX(Calc!$P$2:$P$301,I35)) | F35: =IF(E35="","",IF(E35>=C_BOA,"Boa",IF(E35>=C_ATENCAO,"Atenção","Crítica"))) | H35: =IF(B35="","",IF($C$4="Maiores notas primeiro",LARGE(Calc!$R$2:$R$301,B35),SMALL(Calc!$R$2:$R$301,B35))) | I35: =IF(B35="","",MATCH(H35,Calc!$R$2:$R$301,0))
B36: =IF(30<=COUNT(Calc!$R$2:$R$301),30,"") | C36: =IF(B36="","",INDEX(Calc!$Q$2:$Q$301,I36)) | D36: =IF(B36="","",INDEX(Calc!$O$2:$O$301,I36)) | E36: =IF(B36="","",INDEX(Calc!$P$2:$P$301,I36)) | F36: =IF(E36="","",IF(E36>=C_BOA,"Boa",IF(E36>=C_ATENCAO,"Atenção","Crítica"))) | H36: =IF(B36="","",IF($C$4="Maiores notas primeiro",LARGE(Calc!$R$2:$R$301,B36),SMALL(Calc!$R$2:$R$301,B36))) | I36: =IF(B36="","",MATCH(H36,Calc!$R$2:$R$301,0))
B37: =IF(31<=COUNT(Calc!$R$2:$R$301),31,"") | C37: =IF(B37="","",INDEX(Calc!$Q$2:$Q$301,I37)) | D37: =IF(B37="","",INDEX(Calc!$O$2:$O$301,I37)) | E37: =IF(B37="","",INDEX(Calc!$P$2:$P$301,I37)) | F37: =IF(E37="","",IF(E37>=C_BOA,"Boa",IF(E37>=C_ATENCAO,"Atenção","Crítica"))) | H37: =IF(B37="","",IF($C$4="Maiores notas primeiro",LARGE(Calc!$R$2:$R$301,B37),SMALL(Calc!$R$2:$R$301,B37))) | I37: =IF(B37="","",MATCH(H37,Calc!$R$2:$R$301,0))
B38: =IF(32<=COUNT(Calc!$R$2:$R$301),32,"") | C38: =IF(B38="","",INDEX(Calc!$Q$2:$Q$301,I38)) | D38: =IF(B38="","",INDEX(Calc!$O$2:$O$301,I38)) | E38: =IF(B38="","",INDEX(Calc!$P$2:$P$301,I38)) | F38: =IF(E38="","",IF(E38>=C_BOA,"Boa",IF(E38>=C_ATENCAO,"Atenção","Crítica"))) | H38: =IF(B38="","",IF($C$4="Maiores notas primeiro",LARGE(Calc!$R$2:$R$301,B38),SMALL(Calc!$R$2:$R$301,B38))) | I38: =IF(B38="","",MATCH(H38,Calc!$R$2:$R$301,0))
B39: =IF(33<=COUNT(Calc!$R$2:$R$301),33,"") | C39: =IF(B39="","",INDEX(Calc!$Q$2:$Q$301,I39)) | D39: =IF(B39="","",INDEX(Calc!$O$2:$O$301,I39)) | E39: =IF(B39="","",INDEX(Calc!$P$2:$P$301,I39)) | F39: =IF(E39="","",IF(E39>=C_BOA,"Boa",IF(E39>=C_ATENCAO,"Atenção","Crítica"))) | H39: =IF(B39="","",IF($C$4="Maiores notas primeiro",LARGE(Calc!$R$2:$R$301,B39),SMALL(Calc!$R$2:$R$301,B39))) | I39: =IF(B39="","",MATCH(H39,Calc!$R$2:$R$301,0))
B40: =IF(34<=COUNT(Calc!$R$2:$R$301),34,"") | C40: =IF(B40="","",INDEX(Calc!$Q$2:$Q$301,I40)) | D40: =IF(B40="","",INDEX(Calc!$O$2:$O$301,I40)) | E40: =IF(B40="","",INDEX(Calc!$P$2:$P$301,I40)) | F40: =IF(E40="","",IF(E40>=C_BOA,"Boa",IF(E40>=C_ATENCAO,"Atenção","Crítica"))) | H40: =IF(B40="","",IF($C$4="Maiores notas primeiro",LARGE(Calc!$R$2:$R$301,B40),SMALL(Calc!$R$2:$R$301,B40))) | I40: =IF(B40="","",MATCH(H40,Calc!$R$2:$R$301,0))
B41: =IF(35<=COUNT(Calc!$R$2:$R$301),35,"") | C41: =IF(B41="","",INDEX(Calc!$Q$2:$Q$301,I41)) | D41: =IF(B41="","",INDEX(Calc!$O$2:$O$301,I41)) | E41: =IF(B41="","",INDEX(Calc!$P$2:$P$301,I41)) | F41: =IF(E41="","",IF(E41>=C_BOA,"Boa",IF(E41>=C_ATENCAO,"Atenção","Crítica"))) | H41: =IF(B41="","",IF($C$4="Maiores notas primeiro",LARGE(Calc!$R$2:$R$301,B41),SMALL(Calc!$R$2:$R$301,B41))) | I41: =IF(B41="","",MATCH(H41,Calc!$R$2:$R$301,0))
...

Sheet Ranking Escolas
B1: 4 | C1: ODS 4 · Educação de Qualidade · Recode — Avaliação Escolas
C2: Escolas
C3: Ranking das escolas por nota de qualidade (1 a 5). Use as células em azul claro para filtrar.
B4: Ordem | C4: Maiores notas primeiro | E4: Região | F4: Todas | H4: Tipo | I4: Todos
B5: ="Escolas no filtro: "&COUNT(Calc!$K$2:$K$301)&" · média: "&IFERROR(TEXT(AVERAGEIFS(Calc!$C$2:$C$301,Calc!$K$2:$K$301,">=0"),"0.0"),"—")
B7: # | C7: Escola | D7: Tipo | E7: Região | F7: UF | G7: Nota | H7: Faixa
B8: =IF(1<=COUNT(Calc!$K$2:$K$301),1,"") | C8: =IF(B8="","",INDEX(Calc!$B$2:$B$301,L8)) | D8: =IF(B8="","",INDEX(Calc!$E$2:$E$301,L8)) | E8: =IF(B8="","",INDEX(Calc!$H$2:$H$301,L8)) | F8: =IF(B8="","",INDEX(Calc!$G$2:$G$301,L8)) | G8: =IF(B8="","",INDEX(Calc!$C$2:$C$301,L8)) | H8: =IF(G8="","",IF(G8>=Q_BOA,"Boa",IF(G8>=Q_ATENCAO,"Atenção","Crítica"))) | K8: =IF(B8="","",IF($C$4="Maiores notas primeiro",LARGE(Calc!$K$2:$K$301,B8),SMALL(Calc!$K$2:$K$301,B8))) | L8: =IF(B8="","",MATCH(K8,Calc!$K$2:$K$301,0))
B9: =IF(2<=COUNT(Calc!$K$2:$K$301),2,"") | C9: =IF(B9="","",INDEX(Calc!$B$2:$B$301,L9)) | D9: =IF(B9="","",INDEX(Calc!$E$2:$E$301,L9)) | E9: =IF(B9="","",INDEX(Calc!$H$2:$H$301,L9)) | F9: =IF(B9="","",INDEX(Calc!$G$2:$G$301,L9)) | G9: =IF(B9="","",INDEX(Calc!$C$2:$C$301,L9)) | H9: =IF(G9="","",IF(G9>=Q_BOA,"Boa",IF(G9>=Q_ATENCAO,"Atenção","Crítica"))) | K9: =IF(B9="","",IF($C$4="Maiores notas primeiro",LARGE(Calc!$K$2:$K$301,B9),SMALL(Calc!$K$2:$K$301,B9))) | L9: =IF(B9="","",MATCH(K9,Calc!$K$2:$K$301,0))
B10: =IF(3<=COUNT(Calc!$K$2:$K$301),3,"") | C10: =IF(B10="","",INDEX(Calc!$B$2:$B$301,L10)) | D10: =IF(B10="","",INDEX(Calc!$E$2:$E$301,L10)) | E10: =IF(B10="","",INDEX(Calc!$H$2:$H$301,L10)) | F10: =IF(B10="","",INDEX(Calc!$G$2:$G$301,L10)) | G10: =IF(B10="","",INDEX(Calc!$C$2:$C$301,L10)) | H10: =IF(G10="","",IF(G10>=Q_BOA,"Boa",IF(G10>=Q_ATENCAO,"Atenção","Crítica"))) | K10: =IF(B10="","",IF($C$4="Maiores notas primeiro",LARGE(Calc!$K$2:$K$301,B10),SMALL(Calc!$K$2:$K$301,B10))) | L10: =IF(B10="","",MATCH(K10,Calc!$K$2:$K$301,0))
B11: =IF(4<=COUNT(Calc!$K$2:$K$301),4,"") | C11: =IF(B11="","",INDEX(Calc!$B$2:$B$301,L11)) | D11: =IF(B11="","",INDEX(Calc!$E$2:$E$301,L11)) | E11: =IF(B11="","",INDEX(Calc!$H$2:$H$301,L11)) | F11: =IF(B11="","",INDEX(Calc!$G$2:$G$301,L11)) | G11: =IF(B11="","",INDEX(Calc!$C$2:$C$301,L11)) | H11: =IF(G11="","",IF(G11>=Q_BOA,"Boa",IF(G11>=Q_ATENCAO,"Atenção","Crítica"))) | K11: =IF(B11="","",IF($C$4="Maiores notas primeiro",LARGE(Calc!$K$2:$K$301,B11),SMALL(Calc!$K$2:$K$301,B11))) | L11: =IF(B11="","",MATCH(K11,Calc!$K$2:$K$301,0))
B12: =IF(5<=COUNT(Calc!$K$2:$K$301),5,"") | C12: =IF(B12="","",INDEX(Calc!$B$2:$B$301,L12)) | D12: =IF(B12="","",INDEX(Calc!$E$2:$E$301,L12)) | E12: =IF(B12="","",INDEX(Calc!$H$2:$H$301,L12)) | F12: =IF(B12="","",INDEX(Calc!$G$2:$G$301,L12)) | G12: =IF(B12="","",INDEX(Calc!$C$2:$C$301,L12)) | H12: =IF(G12="","",IF(G12>=Q_BOA,"Boa",IF(G12>=Q_ATENCAO,"Atenção","Crítica"))) | K12: =IF(B12="","",IF($C$4="Maiores notas primeiro",LARGE(Calc!$K$2:$K$301,B12),SMALL(Calc!$K$2:$K$301,B12))) | L12: =IF(B12="","",MATCH(K12,Calc!$K$2:$K$301,0))
B13: =IF(6<=COUNT(Calc!$K$2:$K$301),6,"") | C13: =IF(B13="","",INDEX(Calc!$B$2:$B$301,L13)) | D13: =IF(B13="","",INDEX(Calc!$E$2:$E$301,L13)) | E13: =IF(B13="","",INDEX(Calc!$H$2:$H$301,L13)) | F13: =IF(B13="","",INDEX(Calc!$G$2:$G$301,L13)) | G13: =IF(B13="","",INDEX(Calc!$C$2:$C$301,L13)) | H13: =IF(G13="","",IF(G13>=Q_BOA,"Boa",IF(G13>=Q_ATENCAO,"Atenção","Crítica"))) | K13: =IF(B13="","",IF($C$4="Maiores notas primeiro",LARGE(Calc!$K$2:$K$301,B13),SMALL(Calc!$K$2:$K$301,B13))) | L13: =IF(B13="","",MATCH(K13,Calc!$K$2:$K$301,0))
B14: =IF(7<=COUNT(Calc!$K$2:$K$301),7,"") | C14: =IF(B14="","",INDEX(Calc!$B$2:$B$301,L14)) | D14: =IF(B14="","",INDEX(Calc!$E$2:$E$301,L14)) | E14: =IF(B14="","",INDEX(Calc!$H$2:$H$301,L14)) | F14: =IF(B14="","",INDEX(Calc!$G$2:$G$301,L14)) | G14: =IF(B14="","",INDEX(Calc!$C$2:$C$301,L14)) | H14: =IF(G14="","",IF(G14>=Q_BOA,"Boa",IF(G14>=Q_ATENCAO,"Atenção","Crítica"))) | K14: =IF(B14="","",IF($C$4="Maiores notas primeiro",LARGE(Calc!$K$2:$K$301,B14),SMALL(Calc!$K$2:$K$301,B14))) | L14: =IF(B14="","",MATCH(K14,Calc!$K$2:$K$301,0))
B15: =IF(8<=COUNT(Calc!$K$2:$K$301),8,"") | C15: =IF(B15="","",INDEX(Calc!$B$2:$B$301,L15)) | D15: =IF(B15="","",INDEX(Calc!$E$2:$E$301,L15)) | E15: =IF(B15="","",INDEX(Calc!$H$2:$H$301,L15)) | F15: =IF(B15="","",INDEX(Calc!$G$2:$G$301,L15)) | G15: =IF(B15="","",INDEX(Calc!$C$2:$C$301,L15)) | H15: =IF(G15="","",IF(G15>=Q_BOA,"Boa",IF(G15>=Q_ATENCAO,"Atenção","Crítica"))) | K15: =IF(B15="","",IF($C$4="Maiores notas primeiro",LARGE(Calc!$K$2:$K$301,B15),SMALL(Calc!$K$2:$K$301,B15))) | L15: =IF(B15="","",MATCH(K15,Calc!$K$2:$K$301,0))
B16: =IF(9<=COUNT(Calc!$K$2:$K$301),9,"") | C16: =IF(B16="","",INDEX(Calc!$B$2:$B$301,L16)) | D16: =IF(B16="","",INDEX(Calc!$E$2:$E$301,L16)) | E16: =IF(B16="","",INDEX(Calc!$H$2:$H$301,L16)) | F16: =IF(B16="","",INDEX(Calc!$G$2:$G$301,L16)) | G16: =IF(B16="","",INDEX(Calc!$C$2:$C$301,L16)) | H16: =IF(G16="","",IF(G16>=Q_BOA,"Boa",IF(G16>=Q_ATENCAO,"Atenção","Crítica"))) | K16: =IF(B16="","",IF($C$4="Maiores notas primeiro",LARGE(Calc!$K$2:$K$301,B16),SMALL(Calc!$K$2:$K$301,B16))) | L16: =IF(B16="","",MATCH(K16,Calc!$K$2:$K$301,0))
B17: =IF(10<=COUNT(Calc!$K$2:$K$301),10,"") | C17: =IF(B17="","",INDEX(Calc!$B$2:$B$301,L17)) | D17: =IF(B17="","",INDEX(Calc!$E$2:$E$301,L17)) | E17: =IF(B17="","",INDEX(Calc!$H$2:$H$301,L17)) | F17: =IF(B17="","",INDEX(Calc!$G$2:$G$301,L17)) | G17: =IF(B17="","",INDEX(Calc!$C$2:$C$301,L17)) | H17: =IF(G17="","",IF(G17>=Q_BOA,"Boa",IF(G17>=Q_ATENCAO,"Atenção","Crítica"))) | K17: =IF(B17="","",IF($C$4="Maiores notas primeiro",LARGE(Calc!$K$2:$K$301,B17),SMALL(Calc!$K$2:$K$301,B17))) | L17: =IF(B17="","",MATCH(K17,Calc!$K$2:$K$301,0))
B18: =IF(11<=COUNT(Calc!$K$2:$K$301),11,"") | C18: =IF(B18="","",INDEX(Calc!$B$2:$B$301,L18)) | D18: =IF(B18="","",INDEX(Calc!$E$2:$E$301,L18)) | E18: =IF(B18="","",INDEX(Calc!$H$2:$H$301,L18)) | F18: =IF(B18="","",INDEX(Calc!$G$2:$G$301,L18)) | G18: =IF(B18="","",INDEX(Calc!$C$2:$C$301,L18)) | H18: =IF(G18="","",IF(G18>=Q_BOA,"Boa",IF(G18>=Q_ATENCAO,"Atenção","Crítica"))) | K18: =IF(B18="","",IF($C$4="Maiores notas primeiro",LARGE(Calc!$K$2:$K$301,B18),SMALL(Calc!$K$2:$K$301,B18))) | L18: =IF(B18="","",MATCH(K18,Calc!$K$2:$K$301,0))
B19: =IF(12<=COUNT(Calc!$K$2:$K$301),12,"") | C19: =IF(B19="","",INDEX(Calc!$B$2:$B$301,L19)) | D19: =IF(B19="","",INDEX(Calc!$E$2:$E$301,L19)) | E19: =IF(B19="","",INDEX(Calc!$H$2:$H$301,L19)) | F19: =IF(B19="","",INDEX(Calc!$G$2:$G$301,L19)) | G19: =IF(B19="","",INDEX(Calc!$C$2:$C$301,L19)) | H19: =IF(G19="","",IF(G19>=Q_BOA,"Boa",IF(G19>=Q_ATENCAO,"Atenção","Crítica"))) | K19: =IF(B19="","",IF($C$4="Maiores notas primeiro",LARGE(Calc!$K$2:$K$301,B19),SMALL(Calc!$K$2:$K$301,B19))) | L19: =IF(B19="","",MATCH(K19,Calc!$K$2:$K$301,0))
B20: =IF(13<=COUNT(Calc!$K$2:$K$301),13,"") | C20: =IF(B20="","",INDEX(Calc!$B$2:$B$301,L20)) | D20: =IF(B20="","",INDEX(Calc!$E$2:$E$301,L20)) | E20: =IF(B20="","",INDEX(Calc!$H$2:$H$301,L20)) | F20: =IF(B20="","",INDEX(Calc!$G$2:$G$301,L20)) | G20: =IF(B20="","",INDEX(Calc!$C$2:$C$301,L20)) | H20: =IF(G20="","",IF(G20>=Q_BOA,"Boa",IF(G20>=Q_ATENCAO,"Atenção","Crítica"))) | K20: =IF(B20="","",IF($C$4="Maiores notas primeiro",LARGE(Calc!$K$2:$K$301,B20),SMALL(Calc!$K$2:$K$301,B20))) | L20: =IF(B20="","",MATCH(K20,Calc!$K$2:$K$301,0))
B21: =IF(14<=COUNT(Calc!$K$2:$K$301),14,"") | C21: =IF(B21="","",INDEX(Calc!$B$2:$B$301,L21)) | D21: =IF(B21="","",INDEX(Calc!$E$2:$E$301,L21)) | E21: =IF(B21="","",INDEX(Calc!$H$2:$H$301,L21)) | F21: =IF(B21="","",INDEX(Calc!$G$2:$G$301,L21)) | G21: =IF(B21="","",INDEX(Calc!$C$2:$C$301,L21)) | H21: =IF(G21="","",IF(G21>=Q_BOA,"Boa",IF(G21>=Q_ATENCAO,"Atenção","Crítica"))) | K21: =IF(B21="","",IF($C$4="Maiores notas primeiro",LARGE(Calc!$K$2:$K$301,B21),SMALL(Calc!$K$2:$K$301,B21))) | L21: =IF(B21="","",MATCH(K21,Calc!$K$2:$K$301,0))
B22: =IF(15<=COUNT(Calc!$K$2:$K$301),15,"") | C22: =IF(B22="","",INDEX(Calc!$B$2:$B$301,L22)) | D22: =IF(B22="","",INDEX(Calc!$E$2:$E$301,L22)) | E22: =IF(B22="","",INDEX(Calc!$H$2:$H$301,L22)) | F22: =IF(B22="","",INDEX(Calc!$G$2:$G$301,L22)) | G22: =IF(B22="","",INDEX(Calc!$C$2:$C$301,L22)) | H22: =IF(G22="","",IF(G22>=Q_BOA,"Boa",IF(G22>=Q_ATENCAO,"Atenção","Crítica"))) | K22: =IF(B22="","",IF($C$4="Maiores notas primeiro",LARGE(Calc!$K$2:$K$301,B22),SMALL(Calc!$K$2:$K$301,B22))) | L22: =IF(B22="","",MATCH(K22,Calc!$K$2:$K$301,0))
B23: =IF(16<=COUNT(Calc!$K$2:$K$301),16,"") | C23: =IF(B23="","",INDEX(Calc!$B$2:$B$301,L23)) | D23: =IF(B23="","",INDEX(Calc!$E$2:$E$301,L23)) | E23: =IF(B23="","",INDEX(Calc!$H$2:$H$301,L23)) | F23: =IF(B23="","",INDEX(Calc!$G$2:$G$301,L23)) | G23: =IF(B23="","",INDEX(Calc!$C$2:$C$301,L23)) | H23: =IF(G23="","",IF(G23>=Q_BOA,"Boa",IF(G23>=Q_ATENCAO,"Atenção","Crítica"))) | K23: =IF(B23="","",IF($C$4="Maiores notas primeiro",LARGE(Calc!$K$2:$K$301,B23),SMALL(Calc!$K$2:$K$301,B23))) | L23: =IF(B23="","",MATCH(K23,Calc!$K$2:$K$301,0))
B24: =IF(17<=COUNT(Calc!$K$2:$K$301),17,"") | C24: =IF(B24="","",INDEX(Calc!$B$2:$B$301,L24)) | D24: =IF(B24="","",INDEX(Calc!$E$2:$E$301,L24)) | E24: =IF(B24="","",INDEX(Calc!$H$2:$H$301,L24)) | F24: =IF(B24="","",INDEX(Calc!$G$2:$G$301,L24)) | G24: =IF(B24="","",INDEX(Calc!$C$2:$C$301,L24)) | H24: =IF(G24="","",IF(G24>=Q_BOA,"Boa",IF(G24>=Q_ATENCAO,"Atenção","Crítica"))) | K24: =IF(B24="","",IF($C$4="Maiores notas primeiro",LARGE(Calc!$K$2:$K$301,B24),SMALL(Calc!$K$2:$K$301,B24))) | L24: =IF(B24="","",MATCH(K24,Calc!$K$2:$K$301,0))
B25: =IF(18<=COUNT(Calc!$K$2:$K$301),18,"") | C25: =IF(B25="","",INDEX(Calc!$B$2:$B$301,L25)) | D25: =IF(B25="","",INDEX(Calc!$E$2:$E$301,L25)) | E25: =IF(B25="","",INDEX(Calc!$H$2:$H$301,L25)) | F25: =IF(B25="","",INDEX(Calc!$G$2:$G$301,L25)) | G25: =IF(B25="","",INDEX(Calc!$C$2:$C$301,L25)) | H25: =IF(G25="","",IF(G25>=Q_BOA,"Boa",IF(G25>=Q_ATENCAO,"Atenção","Crítica"))) | K25: =IF(B25="","",IF($C$4="Maiores notas primeiro",LARGE(Calc!$K$2:$K$301,B25),SMALL(Calc!$K$2:$K$301,B25))) | L25: =IF(B25="","",MATCH(K25,Calc!$K$2:$K$301,0))
B26: =IF(19<=COUNT(Calc!$K$2:$K$301),19,"") | C26: =IF(B26="","",INDEX(Calc!$B$2:$B$301,L26)) | D26: =IF(B26="","",INDEX(Calc!$E$2:$E$301,L26)) | E26: =IF(B26="","",INDEX(Calc!$H$2:$H$301,L26)) | F26: =IF(B26="","",INDEX(Calc!$G$2:$G$301,L26)) | G26: =IF(B26="","",INDEX(Calc!$C$2:$C$301,L26)) | H26: =IF(G26="","",IF(G26>=Q_BOA,"Boa",IF(G26>=Q_ATENCAO,"Atenção","Crítica"))) | K26: =IF(B26="","",IF($C$4="Maiores notas primeiro",LARGE(Calc!$K$2:$K$301,B26),SMALL(Calc!$K$2:$K$301,B26))) | L26: =IF(B26="","",MATCH(K26,Calc!$K$2:$K$301,0))
B27: =IF(20<=COUNT(Calc!$K$2:$K$301),20,"") | C27: =IF(B27="","",INDEX(Calc!$B$2:$B$301,L27)) | D27: =IF(B27="","",INDEX(Calc!$E$2:$E$301,L27)) | E27: =IF(B27="","",INDEX(Calc!$H$2:$H$301,L27)) | F27: =IF(B27="","",INDEX(Calc!$G$2:$G$301,L27)) | G27: =IF(B27="","",INDEX(Calc!$C$2:$C$301,L27)) | H27: =IF(G27="","",IF(G27>=Q_BOA,"Boa",IF(G27>=Q_ATENCAO,"Atenção","Crítica"))) | K27: =IF(B27="","",IF($C$4="Maiores notas primeiro",LARGE(Calc!$K$2:$K$301,B27),SMALL(Calc!$K$2:$K$301,B27))) | L27: =IF(B27="","",MATCH(K27,Calc!$K$2:$K$301,0))
B28: =IF(21<=COUNT(Calc!$K$2:$K$301),21,"") | C28: =IF(B28="","",INDEX(Calc!$B$2:$B$301,L28)) | D28: =IF(B28="","",INDEX(Calc!$E$2:$E$301,L28)) | E28: =IF(B28="","",INDEX(Calc!$H$2:$H$301,L28)) | F28: =IF(B28="","",INDEX(Calc!$G$2:$G$301,L28)) | G28: =IF(B28="","",INDEX(Calc!$C$2:$C$301,L28)) | H28: =IF(G28="","",IF(G28>=Q_BOA,"Boa",IF(G28>=Q_ATENCAO,"Atenção","Crítica"))) | K28: =IF(B28="","",IF($C$4="Maiores notas primeiro",LARGE(Calc!$K$2:$K$301,B28),SMALL(Calc!$K$2:$K$301,B28))) | L28: =IF(B28="","",MATCH(K28,Calc!$K$2:$K$301,0))
B29: =IF(22<=COUNT(Calc!$K$2:$K$301),22,"") | C29: =IF(B29="","",INDEX(Calc!$B$2:$B$301,L29)) | D29: =IF(B29="","",INDEX(Calc!$E$2:$E$301,L29)) | E29: =IF(B29="","",INDEX(Calc!$H$2:$H$301,L29)) | F29: =IF(B29="","",INDEX(Calc!$G$2:$G$301,L29)) | G29: =IF(B29="","",INDEX(Calc!$C$2:$C$301,L29)) | H29: =IF(G29="","",IF(G29>=Q_BOA,"Boa",IF(G29>=Q_ATENCAO,"Atenção","Crítica"))) | K29: =IF(B29="","",IF($C$4="Maiores notas primeiro",LARGE(Calc!$K$2:$K$301,B29),SMALL(Calc!$K$2:$K$301,B29))) | L29: =IF(B29="","",MATCH(K29,Calc!$K$2:$K$301,0))
B30: =IF(23<=COUNT(Calc!$K$2:$K$301),23,"") | C30: =IF(B30="","",INDEX(Calc!$B$2:$B$301,L30)) | D30: =IF(B30="","",INDEX(Calc!$E$2:$E$301,L30)) | E30: =IF(B30="","",INDEX(Calc!$H$2:$H$301,L30)) | F30: =IF(B30="","",INDEX(Calc!$G$2:$G$301,L30)) | G30: =IF(B30="","",INDEX(Calc!$C$2:$C$301,L30)) | H30: =IF(G30="","",IF(G30>=Q_BOA,"Boa",IF(G30>=Q_ATENCAO,"Atenção","Crítica"))) | K30: =IF(B30="","",IF($C$4="Maiores notas primeiro",LARGE(Calc!$K$2:$K$301,B30),SMALL(Calc!$K$2:$K$301,B30))) | L30: =IF(B30="","",MATCH(K30,Calc!$K$2:$K$301,0))
B31: =IF(24<=COUNT(Calc!$K$2:$K$301),24,"") | C31: =IF(B31="","",INDEX(Calc!$B$2:$B$301,L31)) | D31: =IF(B31="","",INDEX(Calc!$E$2:$E$301,L31)) | E31: =IF(B31="","",INDEX(Calc!$H$2:$H$301,L31)) | F31: =IF(B31="","",INDEX(Calc!$G$2:$G$301,L31)) | G31: =IF(B31="","",INDEX(Calc!$C$2:$C$301,L31)) | H31: =IF(G31="","",IF(G31>=Q_BOA,"Boa",IF(G31>=Q_ATENCAO,"Atenção","Crítica"))) | K31: =IF(B31="","",IF($C$4="Maiores notas primeiro",LARGE(Calc!$K$2:$K$301,B31),SMALL(Calc!$K$2:$K$301,B31))) | L31: =IF(B31="","",MATCH(K31,Calc!$K$2:$K$301,0))
B32: =IF(25<=COUNT(Calc!$K$2:$K$301),25,"") | C32: =IF(B32="","",INDEX(Calc!$B$2:$B$301,L32)) | D32: =IF(B32="","",INDEX(Calc!$E$2:$E$301,L32)) | E32: =IF(B32="","",INDEX(Calc!$H$2:$H$301,L32)) | F32: =IF(B32="","",INDEX(Calc!$G$2:$G$301,L32)) | G32: =IF(B32="","",INDEX(Calc!$C$2:$C$301,L32)) | H32: =IF(G32="","",IF(G32>=Q_BOA,"Boa",IF(G32>=Q_ATENCAO,"Atenção","Crítica"))) | K32: =IF(B32="","",IF($C$4="Maiores notas primeiro",LARGE(Calc!$K$2:$K$301,B32),SMALL(Calc!$K$2:$K$301,B32))) | L32: =IF(B32="","",MATCH(K32,Calc!$K$2:$K$301,0))
B33: =IF(26<=COUNT(Calc!$K$2:$K$301),26,"") | C33: =IF(B33="","",INDEX(Calc!$B$2:$B$301,L33)) | D33: =IF(B33="","",INDEX(Calc!$E$2:$E$301,L33)) | E33: =IF(B33="","",INDEX(Calc!$H$2:$H$301,L33)) | F33: =IF(B33="","",INDEX(Calc!$G$2:$G$301,L33)) | G33: =IF(B33="","",INDEX(Calc!$C$2:$C$301,L33)) | H33: =IF(G33="","",IF(G33>=Q_BOA,"Boa",IF(G33>=Q_ATENCAO,"Atenção","Crítica"))) | K33: =IF(B33="","",IF($C$4="Maiores notas primeiro",LARGE(Calc!$K$2:$K$301,B33),SMALL(Calc!$K$2:$K$301,B33))) | L33: =IF(B33="","",MATCH(K33,Calc!$K$2:$K$301,0))
B34: =IF(27<=COUNT(Calc!$K$2:$K$301),27,"") | C34: =IF(B34="","",INDEX(Calc!$B$2:$B$301,L34)) | D34: =IF(B34="","",INDEX(Calc!$E$2:$E$301,L34)) | E34: =IF(B34="","",INDEX(Calc!$H$2:$H$301,L34)) | F34: =IF(B34="","",INDEX(Calc!$G$2:$G$301,L34)) | G34: =IF(B34="","",INDEX(Calc!$C$2:$C$301,L34)) | H34: =IF(G34="","",IF(G34>=Q_BOA,"Boa",IF(G34>=Q_ATENCAO,"Atenção","Crítica"))) | K34: =IF(B34="","",IF($C$4="Maiores notas primeiro",LARGE(Calc!$K$2:$K$301,B34),SMALL(Calc!$K$2:$K$301,B34))) | L34: =IF(B34="","",MATCH(K34,Calc!$K$2:$K$301,0))
B35: =IF(28<=COUNT(Calc!$K$2:$K$301),28,"") | C35: =IF(B35="","",INDEX(Calc!$B$2:$B$301,L35)) | D35: =IF(B35="","",INDEX(Calc!$E$2:$E$301,L35)) | E35: =IF(B35="","",INDEX(Calc!$H$2:$H$301,L35)) | F35: =IF(B35="","",INDEX(Calc!$G$2:$G$301,L35)) | G35: =IF(B35="","",INDEX(Calc!$C$2:$C$301,L35)) | H35: =IF(G35="","",IF(G35>=Q_BOA,"Boa",IF(G35>=Q_ATENCAO,"Atenção","Crítica"))) | K35: =IF(B35="","",IF($C$4="Maiores notas primeiro",LARGE(Calc!$K$2:$K$301,B35),SMALL(Calc!$K$2:$K$301,B35))) | L35: =IF(B35="","",MATCH(K35,Calc!$K$2:$K$301,0))
B36: =IF(29<=COUNT(Calc!$K$2:$K$301),29,"") | C36: =IF(B36="","",INDEX(Calc!$B$2:$B$301,L36)) | D36: =IF(B36="","",INDEX(Calc!$E$2:$E$301,L36)) | E36: =IF(B36="","",INDEX(Calc!$H$2:$H$301,L36)) | F36: =IF(B36="","",INDEX(Calc!$G$2:$G$301,L36)) | G36: =IF(B36="","",INDEX(Calc!$C$2:$C$301,L36)) | H36: =IF(G36="","",IF(G36>=Q_BOA,"Boa",IF(G36>=Q_ATENCAO,"Atenção","Crítica"))) | K36: =IF(B36="","",IF($C$4="Maiores notas primeiro",LARGE(Calc!$K$2:$K$301,B36),SMALL(Calc!$K$2:$K$301,B36))) | L36: =IF(B36="","",MATCH(K36,Calc!$K$2:$K$301,0))
B37: =IF(30<=COUNT(Calc!$K$2:$K$301),30,"") | C37: =IF(B37="","",INDEX(Calc!$B$2:$B$301,L37)) | D37: =IF(B37="","",INDEX(Calc!$E$2:$E$301,L37)) | E37: =IF(B37="","",INDEX(Calc!$H$2:$H$301,L37)) | F37: =IF(B37="","",INDEX(Calc!$G$2:$G$301,L37)) | G37: =IF(B37="","",INDEX(Calc!$C$2:$C$301,L37)) | H37: =IF(G37="","",IF(G37>=Q_BOA,"Boa",IF(G37>=Q_ATENCAO,"Atenção","Crítica"))) | K37: =IF(B37="","",IF($C$4="Maiores notas primeiro",LARGE(Calc!$K$2:$K$301,B37),SMALL(Calc!$K$2:$K$301,B37))) | L37: =IF(B37="","",MATCH(K37,Calc!$K$2:$K$301,0))
B38: =IF(31<=COUNT(Calc!$K$2:$K$301),31,"") | C38: =IF(B38="","",INDEX(Calc!$B$2:$B$301,L38)) | D38: =IF(B38="","",INDEX(Calc!$E$2:$E$301,L38)) | E38: =IF(B38="","",INDEX(Calc!$H$2:$H$301,L38)) | F38: =IF(B38="","",INDEX(Calc!$G$2:$G$301,L38)) | G38: =IF(B38="","",INDEX(Calc!$C$2:$C$301,L38)) | H38: =IF(G38="","",IF(G38>=Q_BOA,"Boa",IF(G38>=Q_ATENCAO,"Atenção","Crítica"))) | K38: =IF(B38="","",IF($C$4="Maiores notas primeiro",LARGE(Calc!$K$2:$K$301,B38),SMALL(Calc!$K$2:$K$301,B38))) | L38: =IF(B38="","",MATCH(K38,Calc!$K$2:$K$301,0))
B39: =IF(32<=COUNT(Calc!$K$2:$K$301),32,"") | C39: =IF(B39="","",INDEX(Calc!$B$2:$B$301,L39)) | D39: =IF(B39="","",INDEX(Calc!$E$2:$E$301,L39)) | E39: =IF(B39="","",INDEX(Calc!$H$2:$H$301,L39)) | F39: =IF(B39="","",INDEX(Calc!$G$2:$G$301,L39)) | G39: =IF(B39="","",INDEX(Calc!$C$2:$C$301,L39)) | H39: =IF(G39="","",IF(G39>=Q_BOA,"Boa",IF(G39>=Q_ATENCAO,"Atenção","Crítica"))) | K39: =IF(B39="","",IF($C$4="Maiores notas primeiro",LARGE(Calc!$K$2:$K$301,B39),SMALL(Calc!$K$2:$K$301,B39))) | L39: =IF(B39="","",MATCH(K39,Calc!$K$2:$K$301,0))
B40: =IF(33<=COUNT(Calc!$K$2:$K$301),33,"") | C40: =IF(B40="","",INDEX(Calc!$B$2:$B$301,L40)) | D40: =IF(B40="","",INDEX(Calc!$E$2:$E$301,L40)) | E40: =IF(B40="","",INDEX(Calc!$H$2:$H$301,L40)) | F40: =IF(B40="","",INDEX(Calc!$G$2:$G$301,L40)) | G40: =IF(B40="","",INDEX(Calc!$C$2:$C$301,L40)) | H40: =IF(G40="","",IF(G40>=Q_BOA,"Boa",IF(G40>=Q_ATENCAO,"Atenção","Crítica"))) | K40: =IF(B40="","",IF($C$4="Maiores notas primeiro",LARGE(Calc!$K$2:$K$301,B40),SMALL(Calc!$K$2:$K$301,B40))) | L40: =IF(B40="","",MATCH(K40,Calc!$K$2:$K$301,0))
B41: =IF(34<=COUNT(Calc!$K$2:$K$301),34,"") | C41: =IF(B41="","",INDEX(Calc!$B$2:$B$301,L41)) | D41: =IF(B41="","",INDEX(Calc!$E$2:$E$301,L41)) | E41: =IF(B41="","",INDEX(Calc!$H$2:$H$301,L41)) | F41: =IF(B41="","",INDEX(Calc!$G$2:$G$301,L41)) | G41: =IF(B41="","",INDEX(Calc!$C$2:$C$301,L41)) | H41: =IF(G41="","",IF(G41>=Q_BOA,"Boa",IF(G41>=Q_ATENCAO,"Atenção","Crítica"))) | K41: =IF(B41="","",IF($C$4="Maiores notas primeiro",LARGE(Calc!$K$2:$K$301,B41),SMALL(Calc!$K$2:$K$301,B41))) | L41: =IF(B41="","",MATCH(K41,Calc!$K$2:$K$301,0))
...

Sheet Calc
A1: # | B1: Escola | C1: Nota | D1: Avaliações | E1: Tipo | F1: Tam. cidade | G1: UF | H1: Região | I1: Localização | K1: Chave filtro | M1: # | N1: Curso | O1: Escola | P1: Nota | Q1: Rótulo | R1: Chave | T1: Nota | U1: Escolas
A2: 1 | B2: =IF(A2>ROWS(avaliacoes_qualidade[escola]),"",INDEX(avaliacoes_qualidade[escola],A2)) | C2: =IF(B2="","",INDEX(avaliacoes_qualidade[Nota média],A2)) | D2: =IF(B2="","",INDEX(avaliacoes_qualidade[Avaliações],A2)) | E2: =IF(B2="","",IFERROR(INDEX(escolas[Column1.tipo],MATCH(B2,escolas[Column1.nome],0)),"—")) | F2: =IF(B2="","",SUMPRODUCT(MAX((RIGHT(B2,LEN(enderecos_escolas[cidade])+1)=" "&enderecos_escolas[cidade])*LEN(enderecos_escolas[cidade])))) | G2: =IF(B2="","",IFERROR(INDEX(enderecos_escolas[estado],MATCH(1,INDEX((RIGHT(B2,LEN(enderecos_escolas[cidade])+1)=" "&enderecos_escolas[cidade])*(LEN(enderecos_escolas[cidade])=F2),0),0)),"—")) | H2: =IF(B2="","",IFERROR(VLOOKUP(G2,'Parâmetros'!$A$5:$B$31,2,FALSE),"Não localizada")) | I2: =IF(B2="","",IFERROR(INDEX(enderecos_escolas[tipoLocalizacao],MATCH(1,INDEX((RIGHT(B2,LEN(enderecos_escolas[cidade])+1)=" "&enderecos_escolas[cidade])*(LEN(enderecos_escolas[cidade])=F2),0),0)),"—")) | K2: =IF(C2="","",IF(AND(OR('Ranking Escolas'!$F$4="Todas",H2='Ranking Escolas'!$F$4),OR('Ranking Escolas'!$I$4="Todos",E2='Ranking Escolas'!$I$4)),C2+(1000-A2)/10000000,"")) | M2: 1 | N2: =IF(M2>ROWS(avaliacoes_cursos[curso]),"",INDEX(avaliacoes_cursos[curso],M2)) | O2: =IF(N2="","",INDEX(avaliacoes_cursos[escola],M2)) | P2: =IF(N2="","",INDEX(avaliacoes_cursos[Nota média],M2)) | Q2: =IF(N2="","",IF(COUNTIF(avaliacoes_cursos[curso],N2)>1,N2&" — "&O2,N2)) | R2: =IF(P2="","",P2+(1000-M2)/10000000) | T2: 1 | U2: =COUNTIFS($C$2:$C$301,">="&1-0.5,$C$2:$C$301,"<"&1+0.5)
A3: 2 | B3: =IF(A3>ROWS(avaliacoes_qualidade[escola]),"",INDEX(avaliacoes_qualidade[escola],A3)) | C3: =IF(B3="","",INDEX(avaliacoes_qualidade[Nota média],A3)) | D3: =IF(B3="","",INDEX(avaliacoes_qualidade[Avaliações],A3)) | E3: =IF(B3="","",IFERROR(INDEX(escolas[Column1.tipo],MATCH(B3,escolas[Column1.nome],0)),"—")) | F3: =IF(B3="","",SUMPRODUCT(MAX((RIGHT(B3,LEN(enderecos_escolas[cidade])+1)=" "&enderecos_escolas[cidade])*LEN(enderecos_escolas[cidade])))) | G3: =IF(B3="","",IFERROR(INDEX(enderecos_escolas[estado],MATCH(1,INDEX((RIGHT(B3,LEN(enderecos_escolas[cidade])+1)=" "&enderecos_escolas[cidade])*(LEN(enderecos_escolas[cidade])=F3),0),0)),"—")) | H3: =IF(B3="","",IFERROR(VLOOKUP(G3,'Parâmetros'!$A$5:$B$31,2,FALSE),"Não localizada")) | I3: =IF(B3="","",IFERROR(INDEX(enderecos_escolas[tipoLocalizacao],MATCH(1,INDEX((RIGHT(B3,LEN(enderecos_escolas[cidade])+1)=" "&enderecos_escolas[cidade])*(LEN(enderecos_escolas[cidade])=F3),0),0)),"—")) | K3: =IF(C3="","",IF(AND(OR('Ranking Escolas'!$F$4="Todas",H3='Ranking Escolas'!$F$4),OR('Ranking Escolas'!$I$4="Todos",E3='Ranking Escolas'!$I$4)),C3+(1000-A3)/10000000,"")) | M3: 2 | N3: =IF(M3>ROWS(avaliacoes_cursos[curso]),"",INDEX(avaliacoes_cursos[curso],M3)) | O3: =IF(N3="","",INDEX(avaliacoes_cursos[escola],M3)) | P3: =IF(N3="","",INDEX(avaliacoes_cursos[Nota média],M3)) | Q3: =IF(N3="","",IF(COUNTIF(avaliacoes_cursos[curso],N3)>1,N3&" — "&O3,N3)) | R3: =IF(P3="","",P3+(1000-M3)/10000000) | T3: 2 | U3: =COUNTIFS($C$2:$C$301,">="&2-0.5,$C$2:$C$301,"<"&2+0.5)
A4: 3 | B4: =IF(A4>ROWS(avaliacoes_qualidade[escola]),"",INDEX(avaliacoes_qualidade[escola],A4)) | C4: =IF(B4="","",INDEX(avaliacoes_qualidade[Nota média],A4)) | D4: =IF(B4="","",INDEX(avaliacoes_qualidade[Avaliações],A4)) | E4: =IF(B4="","",IFERROR(INDEX(escolas[Column1.tipo],MATCH(B4,escolas[Column1.nome],0)),"—")) | F4: =IF(B4="","",SUMPRODUCT(MAX((RIGHT(B4,LEN(enderecos_escolas[cidade])+1)=" "&enderecos_escolas[cidade])*LEN(enderecos_escolas[cidade])))) | G4: =IF(B4="","",IFERROR(INDEX(enderecos_escolas[estado],MATCH(1,INDEX((RIGHT(B4,LEN(enderecos_escolas[cidade])+1)=" "&enderecos_escolas[cidade])*(LEN(enderecos_escolas[cidade])=F4),0),0)),"—")) | H4: =IF(B4="","",IFERROR(VLOOKUP(G4,'Parâmetros'!$A$5:$B$31,2,FALSE),"Não localizada")) | I4: =IF(B4="","",IFERROR(INDEX(enderecos_escolas[tipoLocalizacao],MATCH(1,INDEX((RIGHT(B4,LEN(enderecos_escolas[cidade])+1)=" "&enderecos_escolas[cidade])*(LEN(enderecos_escolas[cidade])=F4),0),0)),"—")) | K4: =IF(C4="","",IF(AND(OR('Ranking Escolas'!$F$4="Todas",H4='Ranking Escolas'!$F$4),OR('Ranking Escolas'!$I$4="Todos",E4='Ranking Escolas'!$I$4)),C4+(1000-A4)/10000000,"")) | M4: 3 | N4: =IF(M4>ROWS(avaliacoes_cursos[curso]),"",INDEX(avaliacoes_cursos[curso],M4)) | O4: =IF(N4="","",INDEX(avaliacoes_cursos[escola],M4)) | P4: =IF(N4="","",INDEX(avaliacoes_cursos[Nota média],M4)) | Q4: =IF(N4="","",IF(COUNTIF(avaliacoes_cursos[curso],N4)>1,N4&" — "&O4,N4)) | R4: =IF(P4="","",P4+(1000-M4)/10000000) | T4: 3 | U4: =COUNTIFS($C$2:$C$301,">="&3-0.5,$C$2:$C$301,"<"&3+0.5)
A5: 4 | B5: =IF(A5>ROWS(avaliacoes_qualidade[escola]),"",INDEX(avaliacoes_qualidade[escola],A5)) | C5: =IF(B5="","",INDEX(avaliacoes_qualidade[Nota média],A5)) | D5: =IF(B5="","",INDEX(avaliacoes_qualidade[Avaliações],A5)) | E5: =IF(B5="","",IFERROR(INDEX(escolas[Column1.tipo],MATCH(B5,escolas[Column1.nome],0)),"—")) | F5: =IF(B5="","",SUMPRODUCT(MAX((RIGHT(B5,LEN(enderecos_escolas[cidade])+1)=" "&enderecos_escolas[cidade])*LEN(enderecos_escolas[cidade])))) | G5: =IF(B5="","",IFERROR(INDEX(enderecos_escolas[estado],MATCH(1,INDEX((RIGHT(B5,LEN(enderecos_escolas[cidade])+1)=" "&enderecos_escolas[cidade])*(LEN(enderecos_escolas[cidade])=F5),0),0)),"—")) | H5: =IF(B5="","",IFERROR(VLOOKUP(G5,'Parâmetros'!$A$5:$B$31,2,FALSE),"Não localizada")) | I5: =IF(B5="","",IFERROR(INDEX(enderecos_escolas[tipoLocalizacao],MATCH(1,INDEX((RIGHT(B5,LEN(enderecos_escolas[cidade])+1)=" "&enderecos_escolas[cidade])*(LEN(enderecos_escolas[cidade])=F5),0),0)),"—")) | K5: =IF(C5="","",IF(AND(OR('Ranking Escolas'!$F$4="Todas",H5='Ranking Escolas'!$F$4),OR('Ranking Escolas'!$I$4="Todos",E5='Ranking Escolas'!$I$4)),C5+(1000-A5)/10000000,"")) | M5: 4 | N5: =IF(M5>ROWS(avaliacoes_cursos[curso]),"",INDEX(avaliacoes_cursos[curso],M5)) | O5: =IF(N5="","",INDEX(avaliacoes_cursos[escola],M5)) | P5: =IF(N5="","",INDEX(avaliacoes_cursos[Nota média],M5)) | Q5: =IF(N5="","",IF(COUNTIF(avaliacoes_cursos[curso],N5)>1,N5&" — "&O5,N5)) | R5: =IF(P5="","",P5+(1000-M5)/10000000) | T5: 4 | U5: =COUNTIFS($C$2:$C$301,">="&4-0.5,$C$2:$C$301,"<"&4+0.5)
A6: 5 | B6: =IF(A6>ROWS(avaliacoes_qualidade[escola]),"",INDEX(avaliacoes_qualidade[escola],A6)) | C6: =IF(B6="","",INDEX(avaliacoes_qualidade[Nota média],A6)) | D6: =IF(B6="","",INDEX(avaliacoes_qualidade[Avaliações],A6)) | E6: =IF(B6="","",IFERROR(INDEX(escolas[Column1.tipo],MATCH(B6,escolas[Column1.nome],0)),"—")) | F6: =IF(B6="","",SUMPRODUCT(MAX((RIGHT(B6,LEN(enderecos_escolas[cidade])+1)=" "&enderecos_escolas[cidade])*LEN(enderecos_escolas[cidade])))) | G6: =IF(B6="","",IFERROR(INDEX(enderecos_escolas[estado],MATCH(1,INDEX((RIGHT(B6,LEN(enderecos_escolas[cidade])+1)=" "&enderecos_escolas[cidade])*(LEN(enderecos_escolas[cidade])=F6),0),0)),"—")) | H6: =IF(B6="","",IFERROR(VLOOKUP(G6,'Parâmetros'!$A$5:$B$31,2,FALSE),"Não localizada")) | I6: =IF(B6="","",IFERROR(INDEX(enderecos_escolas[tipoLocalizacao],MATCH(1,INDEX((RIGHT(B6,LEN(enderecos_escolas[cidade])+1)=" "&enderecos_escolas[cidade])*(LEN(enderecos_escolas[cidade])=F6),0),0)),"—")) | K6: =IF(C6="","",IF(AND(OR('Ranking Escolas'!$F$4="Todas",H6='Ranking Escolas'!$F$4),OR('Ranking Escolas'!$I$4="Todos",E6='Ranking Escolas'!$I$4)),C6+(1000-A6)/10000000,"")) | M6: 5 | N6: =IF(M6>ROWS(avaliacoes_cursos[curso]),"",INDEX(avaliacoes_cursos[curso],M6)) | O6: =IF(N6="","",INDEX(avaliacoes_cursos[escola],M6)) | P6: =IF(N6="","",INDEX(avaliacoes_cursos[Nota média],M6)) | Q6: =IF(N6="","",IF(COUNTIF(avaliacoes_cursos[curso],N6)>1,N6&" — "&O6,N6)) | R6: =IF(P6="","",P6+(1000-M6)/10000000) | T6: 5 | U6: =COUNTIFS($C$2:$C$301,">="&4.5)
A7: 6 | B7: =IF(A7>ROWS(avaliacoes_qualidade[escola]),"",INDEX(avaliacoes_qualidade[escola],A7)) | C7: =IF(B7="","",INDEX(avaliacoes_qualidade[Nota média],A7)) | D7: =IF(B7="","",INDEX(avaliacoes_qualidade[Avaliações],A7)) | E7: =IF(B7="","",IFERROR(INDEX(escolas[Column1.tipo],MATCH(B7,escolas[Column1.nome],0)),"—")) | F7: =IF(B7="","",SUMPRODUCT(MAX((RIGHT(B7,LEN(enderecos_escolas[cidade])+1)=" "&enderecos_escolas[cidade])*LEN(enderecos_escolas[cidade])))) | G7: =IF(B7="","",IFERROR(INDEX(enderecos_escolas[estado],MATCH(1,INDEX((RIGHT(B7,LEN(enderecos_escolas[cidade])+1)=" "&enderecos_escolas[cidade])*(LEN(enderecos_escolas[cidade])=F7),0),0)),"—")) | H7: =IF(B7="","",IFERROR(VLOOKUP(G7,'Parâmetros'!$A$5:$B$31,2,FALSE),"Não localizada")) | I7: =IF(B7="","",IFERROR(INDEX(enderecos_escolas[tipoLocalizacao],MATCH(1,INDEX((RIGHT(B7,LEN(enderecos_escolas[cidade])+1)=" "&enderecos_escolas[cidade])*(LEN(enderecos_escolas[cidade])=F7),0),0)),"—")) | K7: =IF(C7="","",IF(AND(OR('Ranking Escolas'!$F$4="Todas",H7='Ranking Escolas'!$F$4),OR('Ranking Escolas'!$I$4="Todos",E7='Ranking Escolas'!$I$4)),C7+(1000-A7)/10000000,"")) | M7: 6 | N7: =IF(M7>ROWS(avaliacoes_cursos[curso]),"",INDEX(avaliacoes_cursos[curso],M7)) | O7: =IF(N7="","",INDEX(avaliacoes_cursos[escola],M7)) | P7: =IF(N7="","",INDEX(avaliacoes_cursos[Nota média],M7)) | Q7: =IF(N7="","",IF(COUNTIF(avaliacoes_cursos[curso],N7)>1,N7&" — "&O7,N7)) | R7: =IF(P7="","",P7+(1000-M7)/10000000)
A8: 7 | B8: =IF(A8>ROWS(avaliacoes_qualidade[escola]),"",INDEX(avaliacoes_qualidade[escola],A8)) | C8: =IF(B8="","",INDEX(avaliacoes_qualidade[Nota média],A8)) | D8: =IF(B8="","",INDEX(avaliacoes_qualidade[Avaliações],A8)) | E8: =IF(B8="","",IFERROR(INDEX(escolas[Column1.tipo],MATCH(B8,escolas[Column1.nome],0)),"—")) | F8: =IF(B8="","",SUMPRODUCT(MAX((RIGHT(B8,LEN(enderecos_escolas[cidade])+1)=" "&enderecos_escolas[cidade])*LEN(enderecos_escolas[cidade])))) | G8: =IF(B8="","",IFERROR(INDEX(enderecos_escolas[estado],MATCH(1,INDEX((RIGHT(B8,LEN(enderecos_escolas[cidade])+1)=" "&enderecos_escolas[cidade])*(LEN(enderecos_escolas[cidade])=F8),0),0)),"—")) | H8: =IF(B8="","",IFERROR(VLOOKUP(G8,'Parâmetros'!$A$5:$B$31,2,FALSE),"Não localizada")) | I8: =IF(B8="","",IFERROR(INDEX(enderecos_escolas[tipoLocalizacao],MATCH(1,INDEX((RIGHT(B8,LEN(enderecos_escolas[cidade])+1)=" "&enderecos_escolas[cidade])*(LEN(enderecos_escolas[cidade])=F8),0),0)),"—")) | K8: =IF(C8="","",IF(AND(OR('Ranking Escolas'!$F$4="Todas",H8='Ranking Escolas'!$F$4),OR('Ranking Escolas'!$I$4="Todos",E8='Ranking Escolas'!$I$4)),C8+(1000-A8)/10000000,"")) | M8: 7 | N8: =IF(M8>ROWS(avaliacoes_cursos[curso]),"",INDEX(avaliacoes_cursos[curso],M8)) | O8: =IF(N8="","",INDEX(avaliacoes_cursos[escola],M8)) | P8: =IF(N8="","",INDEX(avaliacoes_cursos[Nota média],M8)) | Q8: =IF(N8="","",IF(COUNTIF(avaliacoes_cursos[curso],N8)>1,N8&" — "&O8,N8)) | R8: =IF(P8="","",P8+(1000-M8)/10000000)
A9: 8 | B9: =IF(A9>ROWS(avaliacoes_qualidade[escola]),"",INDEX(avaliacoes_qualidade[escola],A9)) | C9: =IF(B9="","",INDEX(avaliacoes_qualidade[Nota média],A9)) | D9: =IF(B9="","",INDEX(avaliacoes_qualidade[Avaliações],A9)) | E9: =IF(B9="","",IFERROR(INDEX(escolas[Column1.tipo],MATCH(B9,escolas[Column1.nome],0)),"—")) | F9: =IF(B9="","",SUMPRODUCT(MAX((RIGHT(B9,LEN(enderecos_escolas[cidade])+1)=" "&enderecos_escolas[cidade])*LEN(enderecos_escolas[cidade])))) | G9: =IF(B9="","",IFERROR(INDEX(enderecos_escolas[estado],MATCH(1,INDEX((RIGHT(B9,LEN(enderecos_escolas[cidade])+1)=" "&enderecos_escolas[cidade])*(LEN(enderecos_escolas[cidade])=F9),0),0)),"—")) | H9: =IF(B9="","",IFERROR(VLOOKUP(G9,'Parâmetros'!$A$5:$B$31,2,FALSE),"Não localizada")) | I9: =IF(B9="","",IFERROR(INDEX(enderecos_escolas[tipoLocalizacao],MATCH(1,INDEX((RIGHT(B9,LEN(enderecos_escolas[cidade])+1)=" "&enderecos_escolas[cidade])*(LEN(enderecos_escolas[cidade])=F9),0),0)),"—")) | K9: =IF(C9="","",IF(AND(OR('Ranking Escolas'!$F$4="Todas",H9='Ranking Escolas'!$F$4),OR('Ranking Escolas'!$I$4="Todos",E9='Ranking Escolas'!$I$4)),C9+(1000-A9)/10000000,"")) | M9: 8 | N9: =IF(M9>ROWS(avaliacoes_cursos[curso]),"",INDEX(avaliacoes_cursos[curso],M9)) | O9: =IF(N9="","",INDEX(avaliacoes_cursos[escola],M9)) | P9: =IF(N9="","",INDEX(avaliacoes_cursos[Nota média],M9)) | Q9: =IF(N9="","",IF(COUNTIF(avaliacoes_cursos[curso],N9)>1,N9&" — "&O9,N9)) | R9: =IF(P9="","",P9+(1000-M9)/10000000)
A10: 9 | B10: =IF(A10>ROWS(avaliacoes_qualidade[escola]),"",INDEX(avaliacoes_qualidade[escola],A10)) | C10: =IF(B10="","",INDEX(avaliacoes_qualidade[Nota média],A10)) | D10: =IF(B10="","",INDEX(avaliacoes_qualidade[Avaliações],A10)) | E10: =IF(B10="","",IFERROR(INDEX(escolas[Column1.tipo],MATCH(B10,escolas[Column1.nome],0)),"—")) | F10: =IF(B10="","",SUMPRODUCT(MAX((RIGHT(B10,LEN(enderecos_escolas[cidade])+1)=" "&enderecos_escolas[cidade])*LEN(enderecos_escolas[cidade])))) | G10: =IF(B10="","",IFERROR(INDEX(enderecos_escolas[estado],MATCH(1,INDEX((RIGHT(B10,LEN(enderecos_escolas[cidade])+1)=" "&enderecos_escolas[cidade])*(LEN(enderecos_escolas[cidade])=F10),0),0)),"—")) | H10: =IF(B10="","",IFERROR(VLOOKUP(G10,'Parâmetros'!$A$5:$B$31,2,FALSE),"Não localizada")) | I10: =IF(B10="","",IFERROR(INDEX(enderecos_escolas[tipoLocalizacao],MATCH(1,INDEX((RIGHT(B10,LEN(enderecos_escolas[cidade])+1)=" "&enderecos_escolas[cidade])*(LEN(enderecos_escolas[cidade])=F10),0),0)),"—")) | K10: =IF(C10="","",IF(AND(OR('Ranking Escolas'!$F$4="Todas",H10='Ranking Escolas'!$F$4),OR('Ranking Escolas'!$I$4="Todos",E10='Ranking Escolas'!$I$4)),C10+(1000-A10)/10000000,"")) | M10: 9 | N10: =IF(M10>ROWS(avaliacoes_cursos[curso]),"",INDEX(avaliacoes_cursos[curso],M10)) | O10: =IF(N10="","",INDEX(avaliacoes_cursos[escola],M10)) | P10: =IF(N10="","",INDEX(avaliacoes_cursos[Nota média],M10)) | Q10: =IF(N10="","",IF(COUNTIF(avaliacoes_cursos[curso],N10)>1,N10&" — "&O10,N10)) | R10: =IF(P10="","",P10+(1000-M10)/10000000)
A11: 10 | B11: =IF(A11>ROWS(avaliacoes_qualidade[escola]),"",INDEX(avaliacoes_qualidade[escola],A11)) | C11: =IF(B11="","",INDEX(avaliacoes_qualidade[Nota média],A11)) | D11: =IF(B11="","",INDEX(avaliacoes_qualidade[Avaliações],A11)) | E11: =IF(B11="","",IFERROR(INDEX(escolas[Column1.tipo],MATCH(B11,escolas[Column1.nome],0)),"—")) | F11: =IF(B11="","",SUMPRODUCT(MAX((RIGHT(B11,LEN(enderecos_escolas[cidade])+1)=" "&enderecos_escolas[cidade])*LEN(enderecos_escolas[cidade])))) | G11: =IF(B11="","",IFERROR(INDEX(enderecos_escolas[estado],MATCH(1,INDEX((RIGHT(B11,LEN(enderecos_escolas[cidade])+1)=" "&enderecos_escolas[cidade])*(LEN(enderecos_escolas[cidade])=F11),0),0)),"—")) | H11: =IF(B11="","",IFERROR(VLOOKUP(G11,'Parâmetros'!$A$5:$B$31,2,FALSE),"Não localizada")) | I11: =IF(B11="","",IFERROR(INDEX(enderecos_escolas[tipoLocalizacao],MATCH(1,INDEX((RIGHT(B11,LEN(enderecos_escolas[cidade])+1)=" "&enderecos_escolas[cidade])*(LEN(enderecos_escolas[cidade])=F11),0),0)),"—")) | K11: =IF(C11="","",IF(AND(OR('Ranking Escolas'!$F$4="Todas",H11='Ranking Escolas'!$F$4),OR('Ranking Escolas'!$I$4="Todos",E11='Ranking Escolas'!$I$4)),C11+(1000-A11)/10000000,"")) | M11: 10 | N11: =IF(M11>ROWS(avaliacoes_cursos[curso]),"",INDEX(avaliacoes_cursos[curso],M11)) | O11: =IF(N11="","",INDEX(avaliacoes_cursos[escola],M11)) | P11: =IF(N11="","",INDEX(avaliacoes_cursos[Nota média],M11)) | Q11: =IF(N11="","",IF(COUNTIF(avaliacoes_cursos[curso],N11)>1,N11&" — "&O11,N11)) | R11: =IF(P11="","",P11+(1000-M11)/10000000)
A12: 11 | B12: =IF(A12>ROWS(avaliacoes_qualidade[escola]),"",INDEX(avaliacoes_qualidade[escola],A12)) | C12: =IF(B12="","",INDEX(avaliacoes_qualidade[Nota média],A12)) | D12: =IF(B12="","",INDEX(avaliacoes_qualidade[Avaliações],A12)) | E12: =IF(B12="","",IFERROR(INDEX(escolas[Column1.tipo],MATCH(B12,escolas[Column1.nome],0)),"—")) | F12: =IF(B12="","",SUMPRODUCT(MAX((RIGHT(B12,LEN(enderecos_escolas[cidade])+1)=" "&enderecos_escolas[cidade])*LEN(enderecos_escolas[cidade])))) | G12: =IF(B12="","",IFERROR(INDEX(enderecos_escolas[estado],MATCH(1,INDEX((RIGHT(B12,LEN(enderecos_escolas[cidade])+1)=" "&enderecos_escolas[cidade])*(LEN(enderecos_escolas[cidade])=F12),0),0)),"—")) | H12: =IF(B12="","",IFERROR(VLOOKUP(G12,'Parâmetros'!$A$5:$B$31,2,FALSE),"Não localizada")) | I12: =IF(B12="","",IFERROR(INDEX(enderecos_escolas[tipoLocalizacao],MATCH(1,INDEX((RIGHT(B12,LEN(enderecos_escolas[cidade])+1)=" "&enderecos_escolas[cidade])*(LEN(enderecos_escolas[cidade])=F12),0),0)),"—")) | K12: =IF(C12="","",IF(AND(OR('Ranking Escolas'!$F$4="Todas",H12='Ranking Escolas'!$F$4),OR('Ranking Escolas'!$I$4="Todos",E12='Ranking Escolas'!$I$4)),C12+(1000-A12)/10000000,"")) | M12: 11 | N12: =IF(M12>ROWS(avaliacoes_cursos[curso]),"",INDEX(avaliacoes_cursos[curso],M12)) | O12: =IF(N12="","",INDEX(avaliacoes_cursos[escola],M12)) | P12: =IF(N12="","",INDEX(avaliacoes_cursos[Nota média],M12)) | Q12: =IF(N12="","",IF(COUNTIF(avaliacoes_cursos[curso],N12)>1,N12&" — "&O12,N12)) | R12: =IF(P12="","",P12+(1000-M12)/10000000)
A13: 12 | B13: =IF(A13>ROWS(avaliacoes_qualidade[escola]),"",INDEX(avaliacoes_qualidade[escola],A13)) | C13: =IF(B13="","",INDEX(avaliacoes_qualidade[Nota média],A13)) | D13: =IF(B13="","",INDEX(avaliacoes_qualidade[Avaliações],A13)) | E13: =IF(B13="","",IFERROR(INDEX(escolas[Column1.tipo],MATCH(B13,escolas[Column1.nome],0)),"—")) | F13: =IF(B13="","",SUMPRODUCT(MAX((RIGHT(B13,LEN(enderecos_escolas[cidade])+1)=" "&enderecos_escolas[cidade])*LEN(enderecos_escolas[cidade])))) | G13: =IF(B13="","",IFERROR(INDEX(enderecos_escolas[estado],MATCH(1,INDEX((RIGHT(B13,LEN(enderecos_escolas[cidade])+1)=" "&enderecos_escolas[cidade])*(LEN(enderecos_escolas[cidade])=F13),0),0)),"—")) | H13: =IF(B13="","",IFERROR(VLOOKUP(G13,'Parâmetros'!$A$5:$B$31,2,FALSE),"Não localizada")) | I13: =IF(B13="","",IFERROR(INDEX(enderecos_escolas[tipoLocalizacao],MATCH(1,INDEX((RIGHT(B13,LEN(enderecos_escolas[cidade])+1)=" "&enderecos_escolas[cidade])*(LEN(enderecos_escolas[cidade])=F13),0),0)),"—")) | K13: =IF(C13="","",IF(AND(OR('Ranking Escolas'!$F$4="Todas",H13='Ranking Escolas'!$F$4),OR('Ranking Escolas'!$I$4="Todos",E13='Ranking Escolas'!$I$4)),C13+(1000-A13)/10000000,"")) | M13: 12 | N13: =IF(M13>ROWS(avaliacoes_cursos[curso]),"",INDEX(avaliacoes_cursos[curso],M13)) | O13: =IF(N13="","",INDEX(avaliacoes_cursos[escola],M13)) | P13: =IF(N13="","",INDEX(avaliacoes_cursos[Nota média],M13)) | Q13: =IF(N13="","",IF(COUNTIF(avaliacoes_cursos[curso],N13)>1,N13&" — "&O13,N13)) | R13: =IF(P13="","",P13+(1000-M13)/10000000)
A14: 13 | B14: =IF(A14>ROWS(avaliacoes_qualidade[escola]),"",INDEX(avaliacoes_qualidade[escola],A14)) | C14: =IF(B14="","",INDEX(avaliacoes_qualidade[Nota média],A14)) | D14: =IF(B14="","",INDEX(avaliacoes_qualidade[Avaliações],A14)) | E14: =IF(B14="","",IFERROR(INDEX(escolas[Column1.tipo],MATCH(B14,escolas[Column1.nome],0)),"—")) | F14: =IF(B14="","",SUMPRODUCT(MAX((RIGHT(B14,LEN(enderecos_escolas[cidade])+1)=" "&enderecos_escolas[cidade])*LEN(enderecos_escolas[cidade])))) | G14: =IF(B14="","",IFERROR(INDEX(enderecos_escolas[estado],MATCH(1,INDEX((RIGHT(B14,LEN(enderecos_escolas[cidade])+1)=" "&enderecos_escolas[cidade])*(LEN(enderecos_escolas[cidade])=F14),0),0)),"—")) | H14: =IF(B14="","",IFERROR(VLOOKUP(G14,'Parâmetros'!$A$5:$B$31,2,FALSE),"Não localizada")) | I14: =IF(B14="","",IFERROR(INDEX(enderecos_escolas[tipoLocalizacao],MATCH(1,INDEX((RIGHT(B14,LEN(enderecos_escolas[cidade])+1)=" "&enderecos_escolas[cidade])*(LEN(enderecos_escolas[cidade])=F14),0),0)),"—")) | K14: =IF(C14="","",IF(AND(OR('Ranking Escolas'!$F$4="Todas",H14='Ranking Escolas'!$F$4),OR('Ranking Escolas'!$I$4="Todos",E14='Ranking Escolas'!$I$4)),C14+(1000-A14)/10000000,"")) | M14: 13 | N14: =IF(M14>ROWS(avaliacoes_cursos[curso]),"",INDEX(avaliacoes_cursos[curso],M14)) | O14: =IF(N14="","",INDEX(avaliacoes_cursos[escola],M14)) | P14: =IF(N14="","",INDEX(avaliacoes_cursos[Nota média],M14)) | Q14: =IF(N14="","",IF(COUNTIF(avaliacoes_cursos[curso],N14)>1,N14&" — "&O14,N14)) | R14: =IF(P14="","",P14+(1000-M14)/10000000)
